{
 "cells": [
  {
   "cell_type": "code",
   "execution_count": null,
   "metadata": {
    "collapsed": true,
    "pycharm": {
     "name": "#%%\n",
     "is_executing": true
    }
   },
   "outputs": [
    {
     "name": "stderr",
     "output_type": "stream",
     "text": [
      "ERROR:root:Internal Python error in the inspect module.\n",
      "Below is the traceback from this internal error.\n",
      "\n",
      "ERROR:root:Internal Python error in the inspect module.\n",
      "Below is the traceback from this internal error.\n",
      "\n",
      "ERROR:root:Internal Python error in the inspect module.\n",
      "Below is the traceback from this internal error.\n",
      "\n"
     ]
    },
    {
     "name": "stdout",
     "output_type": "stream",
     "text": [
      "ERROR! Session/line number was not unique in database. History logging moved to new session 61\n",
      "Traceback (most recent call last):\n",
      "  File \"/Users/kimyoonseo/opt/anaconda3/envs/myvenv/lib/python3.6/site-packages/IPython/core/interactiveshell.py\", line 3343, in run_code\n",
      "    exec(code_obj, self.user_global_ns, self.user_ns)\n",
      "  File \"<ipython-input-12-7b871a40c087>\", line 3, in <module>\n",
      "    hello = tf.constant(\"Hello TensorFlow!\")\n",
      "  File \"/Users/kimyoonseo/opt/anaconda3/envs/myvenv/lib/python3.6/site-packages/tensorflow_core/python/util/module_wrapper.py\", line 193, in __getattr__\n",
      "    set([\n",
      "AttributeError: module 'tensorflow' has no attribute 'constant'\n",
      "\n",
      "During handling of the above exception, another exception occurred:\n",
      "\n",
      "Traceback (most recent call last):\n",
      "  File \"/Users/kimyoonseo/opt/anaconda3/envs/myvenv/lib/python3.6/site-packages/IPython/core/interactiveshell.py\", line 2044, in showtraceback\n",
      "    stb = value._render_traceback_()\n",
      "AttributeError: 'AttributeError' object has no attribute '_render_traceback_'\n",
      "\n",
      "During handling of the above exception, another exception occurred:\n",
      "\n",
      "Traceback (most recent call last):\n",
      "  File \"/Users/kimyoonseo/opt/anaconda3/envs/myvenv/lib/python3.6/site-packages/IPython/core/ultratb.py\", line 1169, in get_records\n",
      "    return _fixed_getinnerframes(etb, number_of_lines_of_context, tb_offset)\n",
      "  File \"/Users/kimyoonseo/opt/anaconda3/envs/myvenv/lib/python3.6/site-packages/IPython/core/ultratb.py\", line 316, in wrapped\n",
      "    return f(*args, **kwargs)\n",
      "  File \"/Users/kimyoonseo/opt/anaconda3/envs/myvenv/lib/python3.6/site-packages/IPython/core/ultratb.py\", line 350, in _fixed_getinnerframes\n",
      "    records = fix_frame_records_filenames(inspect.getinnerframes(etb, context))\n",
      "  File \"/Users/kimyoonseo/opt/anaconda3/envs/myvenv/lib/python3.6/inspect.py\", line 1490, in getinnerframes\n",
      "    frameinfo = (tb.tb_frame,) + getframeinfo(tb, context)\n",
      "  File \"/Users/kimyoonseo/opt/anaconda3/envs/myvenv/lib/python3.6/inspect.py\", line 1448, in getframeinfo\n",
      "    filename = getsourcefile(frame) or getfile(frame)\n",
      "  File \"/Users/kimyoonseo/opt/anaconda3/envs/myvenv/lib/python3.6/inspect.py\", line 696, in getsourcefile\n",
      "    if getattr(getmodule(object, filename), '__loader__', None) is not None:\n",
      "  File \"/Users/kimyoonseo/opt/anaconda3/envs/myvenv/lib/python3.6/inspect.py\", line 733, in getmodule\n",
      "    if ismodule(module) and hasattr(module, '__file__'):\n",
      "  File \"/Users/kimyoonseo/opt/anaconda3/envs/myvenv/lib/python3.6/site-packages/tensorflow/__init__.py\", line 50, in __getattr__\n",
      "    module = self._load()\n",
      "  File \"/Users/kimyoonseo/opt/anaconda3/envs/myvenv/lib/python3.6/site-packages/tensorflow/__init__.py\", line 44, in _load\n",
      "    module = _importlib.import_module(self.__name__)\n",
      "  File \"/Users/kimyoonseo/opt/anaconda3/envs/myvenv/lib/python3.6/importlib/__init__.py\", line 126, in import_module\n",
      "    return _bootstrap._gcd_import(name[level:], package, level)\n",
      "  File \"<frozen importlib._bootstrap>\", line 994, in _gcd_import\n",
      "  File \"<frozen importlib._bootstrap>\", line 971, in _find_and_load\n",
      "  File \"<frozen importlib._bootstrap>\", line 941, in _find_and_load_unlocked\n",
      "  File \"<frozen importlib._bootstrap>\", line 219, in _call_with_frames_removed\n",
      "  File \"<frozen importlib._bootstrap>\", line 994, in _gcd_import\n",
      "  File \"<frozen importlib._bootstrap>\", line 971, in _find_and_load\n",
      "  File \"<frozen importlib._bootstrap>\", line 955, in _find_and_load_unlocked\n",
      "  File \"<frozen importlib._bootstrap>\", line 665, in _load_unlocked\n",
      "  File \"<frozen importlib._bootstrap_external>\", line 678, in exec_module\n",
      "  File \"<frozen importlib._bootstrap>\", line 219, in _call_with_frames_removed\n",
      "  File \"/Users/kimyoonseo/opt/anaconda3/envs/myvenv/lib/python3.6/site-packages/tensorflow_core/__init__.py\", line 42, in <module>\n",
      "    from . _api.v2 import audio\n",
      "  File \"/Users/kimyoonseo/opt/anaconda3/envs/myvenv/lib/python3.6/site-packages/tensorflow_core/_api/v2/audio/__init__.py\", line 10, in <module>\n",
      "    from tensorflow.python.ops.gen_audio_ops import decode_wav\n",
      "  File \"/Users/kimyoonseo/opt/anaconda3/envs/myvenv/lib/python3.6/site-packages/tensorflow_core/python/ops/gen_audio_ops.py\", line 11, in <module>\n",
      "    from tensorflow.python.eager import context as _context\n",
      "  File \"/Users/kimyoonseo/opt/anaconda3/envs/myvenv/lib/python3.6/site-packages/tensorflow_core/python/eager/context.py\", line 29, in <module>\n",
      "    from tensorflow.core.protobuf import config_pb2\n",
      "  File \"/Users/kimyoonseo/opt/anaconda3/envs/myvenv/lib/python3.6/site-packages/tensorflow_core/core/protobuf/config_pb2.py\", line 7, in <module>\n",
      "    from google.protobuf import descriptor as _descriptor\n",
      "ModuleNotFoundError: No module named 'google.protobuf'\n",
      "Traceback (most recent call last):\n",
      "  File \"/Users/kimyoonseo/opt/anaconda3/envs/myvenv/lib/python3.6/site-packages/IPython/core/interactiveshell.py\", line 3343, in run_code\n",
      "    exec(code_obj, self.user_global_ns, self.user_ns)\n",
      "  File \"<ipython-input-12-7b871a40c087>\", line 3, in <module>\n",
      "    hello = tf.constant(\"Hello TensorFlow!\")\n",
      "  File \"/Users/kimyoonseo/opt/anaconda3/envs/myvenv/lib/python3.6/site-packages/tensorflow_core/python/util/module_wrapper.py\", line 193, in __getattr__\n",
      "    set([\n",
      "AttributeError: module 'tensorflow' has no attribute 'constant'\n",
      "\n",
      "During handling of the above exception, another exception occurred:\n",
      "\n",
      "Traceback (most recent call last):\n",
      "  File \"/Users/kimyoonseo/opt/anaconda3/envs/myvenv/lib/python3.6/site-packages/IPython/core/interactiveshell.py\", line 2044, in showtraceback\n",
      "    stb = value._render_traceback_()\n",
      "AttributeError: 'AttributeError' object has no attribute '_render_traceback_'\n",
      "\n",
      "During handling of the above exception, another exception occurred:\n",
      "\n",
      "Traceback (most recent call last):\n",
      "  File \"/Users/kimyoonseo/opt/anaconda3/envs/myvenv/lib/python3.6/site-packages/IPython/core/interactiveshell.py\", line 3263, in run_ast_nodes\n",
      "    if (await self.run_code(code, result,  async_=asy)):\n",
      "  File \"/Users/kimyoonseo/opt/anaconda3/envs/myvenv/lib/python3.6/site-packages/IPython/core/interactiveshell.py\", line 3360, in run_code\n",
      "    self.showtraceback(running_compiled_code=True)\n",
      "  File \"/Users/kimyoonseo/opt/anaconda3/envs/myvenv/lib/python3.6/site-packages/IPython/core/interactiveshell.py\", line 2047, in showtraceback\n",
      "    value, tb, tb_offset=tb_offset)\n",
      "  File \"/Users/kimyoonseo/opt/anaconda3/envs/myvenv/lib/python3.6/site-packages/IPython/core/ultratb.py\", line 1436, in structured_traceback\n",
      "    self, etype, value, tb, tb_offset, number_of_lines_of_context)\n",
      "  File \"/Users/kimyoonseo/opt/anaconda3/envs/myvenv/lib/python3.6/site-packages/IPython/core/ultratb.py\", line 1336, in structured_traceback\n",
      "    self, etype, value, tb, tb_offset, number_of_lines_of_context\n",
      "  File \"/Users/kimyoonseo/opt/anaconda3/envs/myvenv/lib/python3.6/site-packages/IPython/core/ultratb.py\", line 1193, in structured_traceback\n",
      "    tb_offset)\n",
      "  File \"/Users/kimyoonseo/opt/anaconda3/envs/myvenv/lib/python3.6/site-packages/IPython/core/ultratb.py\", line 1150, in format_exception_as_a_whole\n",
      "    last_unique, recursion_repeat = find_recursion(orig_etype, evalue, records)\n",
      "  File \"/Users/kimyoonseo/opt/anaconda3/envs/myvenv/lib/python3.6/site-packages/IPython/core/ultratb.py\", line 451, in find_recursion\n",
      "    return len(records), 0\n",
      "TypeError: object of type 'NoneType' has no len()\n",
      "\n",
      "During handling of the above exception, another exception occurred:\n",
      "\n",
      "Traceback (most recent call last):\n",
      "  File \"/Users/kimyoonseo/opt/anaconda3/envs/myvenv/lib/python3.6/site-packages/IPython/core/interactiveshell.py\", line 2044, in showtraceback\n",
      "    stb = value._render_traceback_()\n",
      "AttributeError: 'TypeError' object has no attribute '_render_traceback_'\n",
      "\n",
      "During handling of the above exception, another exception occurred:\n",
      "\n",
      "Traceback (most recent call last):\n",
      "  File \"/Users/kimyoonseo/opt/anaconda3/envs/myvenv/lib/python3.6/site-packages/IPython/core/ultratb.py\", line 1169, in get_records\n",
      "    return _fixed_getinnerframes(etb, number_of_lines_of_context, tb_offset)\n",
      "  File \"/Users/kimyoonseo/opt/anaconda3/envs/myvenv/lib/python3.6/site-packages/IPython/core/ultratb.py\", line 316, in wrapped\n",
      "    return f(*args, **kwargs)\n",
      "  File \"/Users/kimyoonseo/opt/anaconda3/envs/myvenv/lib/python3.6/site-packages/IPython/core/ultratb.py\", line 350, in _fixed_getinnerframes\n",
      "    records = fix_frame_records_filenames(inspect.getinnerframes(etb, context))\n",
      "  File \"/Users/kimyoonseo/opt/anaconda3/envs/myvenv/lib/python3.6/inspect.py\", line 1490, in getinnerframes\n",
      "    frameinfo = (tb.tb_frame,) + getframeinfo(tb, context)\n",
      "  File \"/Users/kimyoonseo/opt/anaconda3/envs/myvenv/lib/python3.6/inspect.py\", line 1448, in getframeinfo\n",
      "    filename = getsourcefile(frame) or getfile(frame)\n",
      "  File \"/Users/kimyoonseo/opt/anaconda3/envs/myvenv/lib/python3.6/inspect.py\", line 696, in getsourcefile\n",
      "    if getattr(getmodule(object, filename), '__loader__', None) is not None:\n",
      "  File \"/Users/kimyoonseo/opt/anaconda3/envs/myvenv/lib/python3.6/inspect.py\", line 733, in getmodule\n",
      "    if ismodule(module) and hasattr(module, '__file__'):\n",
      "  File \"/Users/kimyoonseo/opt/anaconda3/envs/myvenv/lib/python3.6/site-packages/tensorflow/__init__.py\", line 50, in __getattr__\n",
      "    module = self._load()\n",
      "  File \"/Users/kimyoonseo/opt/anaconda3/envs/myvenv/lib/python3.6/site-packages/tensorflow/__init__.py\", line 44, in _load\n",
      "    module = _importlib.import_module(self.__name__)\n",
      "  File \"/Users/kimyoonseo/opt/anaconda3/envs/myvenv/lib/python3.6/importlib/__init__.py\", line 126, in import_module\n",
      "    return _bootstrap._gcd_import(name[level:], package, level)\n",
      "  File \"<frozen importlib._bootstrap>\", line 994, in _gcd_import\n",
      "  File \"<frozen importlib._bootstrap>\", line 971, in _find_and_load\n",
      "  File \"<frozen importlib._bootstrap>\", line 941, in _find_and_load_unlocked\n",
      "  File \"<frozen importlib._bootstrap>\", line 219, in _call_with_frames_removed\n",
      "  File \"<frozen importlib._bootstrap>\", line 994, in _gcd_import\n",
      "  File \"<frozen importlib._bootstrap>\", line 971, in _find_and_load\n",
      "  File \"<frozen importlib._bootstrap>\", line 955, in _find_and_load_unlocked\n",
      "  File \"<frozen importlib._bootstrap>\", line 665, in _load_unlocked\n",
      "  File \"<frozen importlib._bootstrap_external>\", line 678, in exec_module\n",
      "  File \"<frozen importlib._bootstrap>\", line 219, in _call_with_frames_removed\n",
      "  File \"/Users/kimyoonseo/opt/anaconda3/envs/myvenv/lib/python3.6/site-packages/tensorflow_core/__init__.py\", line 42, in <module>\n",
      "    from . _api.v2 import audio\n",
      "  File \"/Users/kimyoonseo/opt/anaconda3/envs/myvenv/lib/python3.6/site-packages/tensorflow_core/_api/v2/audio/__init__.py\", line 10, in <module>\n",
      "    from tensorflow.python.ops.gen_audio_ops import decode_wav\n",
      "  File \"/Users/kimyoonseo/opt/anaconda3/envs/myvenv/lib/python3.6/site-packages/tensorflow_core/python/ops/gen_audio_ops.py\", line 11, in <module>\n",
      "    from tensorflow.python.eager import context as _context\n",
      "  File \"/Users/kimyoonseo/opt/anaconda3/envs/myvenv/lib/python3.6/site-packages/tensorflow_core/python/eager/context.py\", line 29, in <module>\n",
      "    from tensorflow.core.protobuf import config_pb2\n",
      "  File \"/Users/kimyoonseo/opt/anaconda3/envs/myvenv/lib/python3.6/site-packages/tensorflow_core/core/protobuf/config_pb2.py\", line 7, in <module>\n",
      "    from google.protobuf import descriptor as _descriptor\n",
      "ModuleNotFoundError: No module named 'google.protobuf'\n",
      "Traceback (most recent call last):\n",
      "  File \"/Users/kimyoonseo/opt/anaconda3/envs/myvenv/lib/python3.6/site-packages/IPython/core/interactiveshell.py\", line 3343, in run_code\n",
      "    exec(code_obj, self.user_global_ns, self.user_ns)\n",
      "  File \"<ipython-input-12-7b871a40c087>\", line 3, in <module>\n",
      "    hello = tf.constant(\"Hello TensorFlow!\")\n",
      "  File \"/Users/kimyoonseo/opt/anaconda3/envs/myvenv/lib/python3.6/site-packages/tensorflow_core/python/util/module_wrapper.py\", line 193, in __getattr__\n",
      "    set([\n",
      "AttributeError: module 'tensorflow' has no attribute 'constant'\n",
      "\n",
      "During handling of the above exception, another exception occurred:\n",
      "\n",
      "Traceback (most recent call last):\n",
      "  File \"/Users/kimyoonseo/opt/anaconda3/envs/myvenv/lib/python3.6/site-packages/IPython/core/interactiveshell.py\", line 2044, in showtraceback\n",
      "    stb = value._render_traceback_()\n",
      "AttributeError: 'AttributeError' object has no attribute '_render_traceback_'\n",
      "\n",
      "During handling of the above exception, another exception occurred:\n",
      "\n",
      "Traceback (most recent call last):\n",
      "  File \"/Users/kimyoonseo/opt/anaconda3/envs/myvenv/lib/python3.6/site-packages/IPython/core/interactiveshell.py\", line 3263, in run_ast_nodes\n",
      "    if (await self.run_code(code, result,  async_=asy)):\n",
      "  File \"/Users/kimyoonseo/opt/anaconda3/envs/myvenv/lib/python3.6/site-packages/IPython/core/interactiveshell.py\", line 3360, in run_code\n",
      "    self.showtraceback(running_compiled_code=True)\n",
      "  File \"/Users/kimyoonseo/opt/anaconda3/envs/myvenv/lib/python3.6/site-packages/IPython/core/interactiveshell.py\", line 2047, in showtraceback\n",
      "    value, tb, tb_offset=tb_offset)\n",
      "  File \"/Users/kimyoonseo/opt/anaconda3/envs/myvenv/lib/python3.6/site-packages/IPython/core/ultratb.py\", line 1436, in structured_traceback\n",
      "    self, etype, value, tb, tb_offset, number_of_lines_of_context)\n",
      "  File \"/Users/kimyoonseo/opt/anaconda3/envs/myvenv/lib/python3.6/site-packages/IPython/core/ultratb.py\", line 1336, in structured_traceback\n",
      "    self, etype, value, tb, tb_offset, number_of_lines_of_context\n",
      "  File \"/Users/kimyoonseo/opt/anaconda3/envs/myvenv/lib/python3.6/site-packages/IPython/core/ultratb.py\", line 1193, in structured_traceback\n",
      "    tb_offset)\n",
      "  File \"/Users/kimyoonseo/opt/anaconda3/envs/myvenv/lib/python3.6/site-packages/IPython/core/ultratb.py\", line 1150, in format_exception_as_a_whole\n",
      "    last_unique, recursion_repeat = find_recursion(orig_etype, evalue, records)\n",
      "  File \"/Users/kimyoonseo/opt/anaconda3/envs/myvenv/lib/python3.6/site-packages/IPython/core/ultratb.py\", line 451, in find_recursion\n",
      "    return len(records), 0\n",
      "TypeError: object of type 'NoneType' has no len()\n",
      "\n",
      "During handling of the above exception, another exception occurred:\n",
      "\n",
      "Traceback (most recent call last):\n",
      "  File \"/Users/kimyoonseo/opt/anaconda3/envs/myvenv/lib/python3.6/site-packages/IPython/core/interactiveshell.py\", line 2044, in showtraceback\n",
      "    stb = value._render_traceback_()\n",
      "AttributeError: 'TypeError' object has no attribute '_render_traceback_'\n",
      "\n",
      "During handling of the above exception, another exception occurred:\n",
      "\n",
      "Traceback (most recent call last):\n",
      "  File \"/Users/kimyoonseo/opt/anaconda3/envs/myvenv/lib/python3.6/site-packages/IPython/core/interactiveshell.py\", line 2895, in _run_cell\n",
      "    return runner(coro)\n",
      "  File \"/Users/kimyoonseo/opt/anaconda3/envs/myvenv/lib/python3.6/site-packages/IPython/core/async_helpers.py\", line 68, in _pseudo_sync_runner\n",
      "    coro.send(None)\n",
      "  File \"/Users/kimyoonseo/opt/anaconda3/envs/myvenv/lib/python3.6/site-packages/IPython/core/interactiveshell.py\", line 3072, in run_cell_async\n",
      "    interactivity=interactivity, compiler=compiler, result=result)\n",
      "  File \"/Users/kimyoonseo/opt/anaconda3/envs/myvenv/lib/python3.6/site-packages/IPython/core/interactiveshell.py\", line 3282, in run_ast_nodes\n",
      "    self.showtraceback()\n",
      "  File \"/Users/kimyoonseo/opt/anaconda3/envs/myvenv/lib/python3.6/site-packages/IPython/core/interactiveshell.py\", line 2047, in showtraceback\n",
      "    value, tb, tb_offset=tb_offset)\n",
      "  File \"/Users/kimyoonseo/opt/anaconda3/envs/myvenv/lib/python3.6/site-packages/IPython/core/ultratb.py\", line 1436, in structured_traceback\n",
      "    self, etype, value, tb, tb_offset, number_of_lines_of_context)\n",
      "  File \"/Users/kimyoonseo/opt/anaconda3/envs/myvenv/lib/python3.6/site-packages/IPython/core/ultratb.py\", line 1336, in structured_traceback\n",
      "    self, etype, value, tb, tb_offset, number_of_lines_of_context\n",
      "  File \"/Users/kimyoonseo/opt/anaconda3/envs/myvenv/lib/python3.6/site-packages/IPython/core/ultratb.py\", line 1211, in structured_traceback\n",
      "    chained_exceptions_tb_offset)\n",
      "  File \"/Users/kimyoonseo/opt/anaconda3/envs/myvenv/lib/python3.6/site-packages/IPython/core/ultratb.py\", line 1150, in format_exception_as_a_whole\n",
      "    last_unique, recursion_repeat = find_recursion(orig_etype, evalue, records)\n",
      "  File \"/Users/kimyoonseo/opt/anaconda3/envs/myvenv/lib/python3.6/site-packages/IPython/core/ultratb.py\", line 451, in find_recursion\n",
      "    return len(records), 0\n",
      "TypeError: object of type 'NoneType' has no len()\n",
      "\n",
      "During handling of the above exception, another exception occurred:\n",
      "\n",
      "Traceback (most recent call last):\n",
      "  File \"/Users/kimyoonseo/opt/anaconda3/envs/myvenv/lib/python3.6/site-packages/IPython/core/interactiveshell.py\", line 2044, in showtraceback\n",
      "    stb = value._render_traceback_()\n",
      "AttributeError: 'TypeError' object has no attribute '_render_traceback_'\n",
      "\n",
      "During handling of the above exception, another exception occurred:\n",
      "\n",
      "Traceback (most recent call last):\n",
      "  File \"/Users/kimyoonseo/opt/anaconda3/envs/myvenv/lib/python3.6/site-packages/IPython/core/ultratb.py\", line 1169, in get_records\n",
      "    return _fixed_getinnerframes(etb, number_of_lines_of_context, tb_offset)\n",
      "  File \"/Users/kimyoonseo/opt/anaconda3/envs/myvenv/lib/python3.6/site-packages/IPython/core/ultratb.py\", line 316, in wrapped\n",
      "    return f(*args, **kwargs)\n",
      "  File \"/Users/kimyoonseo/opt/anaconda3/envs/myvenv/lib/python3.6/site-packages/IPython/core/ultratb.py\", line 350, in _fixed_getinnerframes\n",
      "    records = fix_frame_records_filenames(inspect.getinnerframes(etb, context))\n",
      "  File \"/Users/kimyoonseo/opt/anaconda3/envs/myvenv/lib/python3.6/inspect.py\", line 1490, in getinnerframes\n",
      "    frameinfo = (tb.tb_frame,) + getframeinfo(tb, context)\n",
      "  File \"/Users/kimyoonseo/opt/anaconda3/envs/myvenv/lib/python3.6/inspect.py\", line 1448, in getframeinfo\n",
      "    filename = getsourcefile(frame) or getfile(frame)\n",
      "  File \"/Users/kimyoonseo/opt/anaconda3/envs/myvenv/lib/python3.6/inspect.py\", line 696, in getsourcefile\n",
      "    if getattr(getmodule(object, filename), '__loader__', None) is not None:\n",
      "  File \"/Users/kimyoonseo/opt/anaconda3/envs/myvenv/lib/python3.6/inspect.py\", line 733, in getmodule\n",
      "    if ismodule(module) and hasattr(module, '__file__'):\n",
      "  File \"/Users/kimyoonseo/opt/anaconda3/envs/myvenv/lib/python3.6/site-packages/tensorflow/__init__.py\", line 50, in __getattr__\n",
      "    module = self._load()\n",
      "  File \"/Users/kimyoonseo/opt/anaconda3/envs/myvenv/lib/python3.6/site-packages/tensorflow/__init__.py\", line 44, in _load\n",
      "    module = _importlib.import_module(self.__name__)\n",
      "  File \"/Users/kimyoonseo/opt/anaconda3/envs/myvenv/lib/python3.6/importlib/__init__.py\", line 126, in import_module\n",
      "    return _bootstrap._gcd_import(name[level:], package, level)\n",
      "  File \"<frozen importlib._bootstrap>\", line 994, in _gcd_import\n",
      "  File \"<frozen importlib._bootstrap>\", line 971, in _find_and_load\n",
      "  File \"<frozen importlib._bootstrap>\", line 941, in _find_and_load_unlocked\n",
      "  File \"<frozen importlib._bootstrap>\", line 219, in _call_with_frames_removed\n",
      "  File \"<frozen importlib._bootstrap>\", line 994, in _gcd_import\n",
      "  File \"<frozen importlib._bootstrap>\", line 971, in _find_and_load\n",
      "  File \"<frozen importlib._bootstrap>\", line 955, in _find_and_load_unlocked\n",
      "  File \"<frozen importlib._bootstrap>\", line 665, in _load_unlocked\n",
      "  File \"<frozen importlib._bootstrap_external>\", line 678, in exec_module\n",
      "  File \"<frozen importlib._bootstrap>\", line 219, in _call_with_frames_removed\n",
      "  File \"/Users/kimyoonseo/opt/anaconda3/envs/myvenv/lib/python3.6/site-packages/tensorflow_core/__init__.py\", line 42, in <module>\n",
      "    from . _api.v2 import audio\n",
      "  File \"/Users/kimyoonseo/opt/anaconda3/envs/myvenv/lib/python3.6/site-packages/tensorflow_core/_api/v2/audio/__init__.py\", line 10, in <module>\n",
      "    from tensorflow.python.ops.gen_audio_ops import decode_wav\n",
      "  File \"/Users/kimyoonseo/opt/anaconda3/envs/myvenv/lib/python3.6/site-packages/tensorflow_core/python/ops/gen_audio_ops.py\", line 11, in <module>\n",
      "    from tensorflow.python.eager import context as _context\n",
      "  File \"/Users/kimyoonseo/opt/anaconda3/envs/myvenv/lib/python3.6/site-packages/tensorflow_core/python/eager/context.py\", line 29, in <module>\n",
      "    from tensorflow.core.protobuf import config_pb2\n",
      "  File \"/Users/kimyoonseo/opt/anaconda3/envs/myvenv/lib/python3.6/site-packages/tensorflow_core/core/protobuf/config_pb2.py\", line 7, in <module>\n",
      "    from google.protobuf import descriptor as _descriptor\n",
      "ModuleNotFoundError: No module named 'google.protobuf'\n"
     ]
    }
   ],
   "source": [
    "import tensorflow as tf\n",
    "\n",
    "hello = tf.constant(\"Hello TensorFlow!\")\n",
    "\n",
    "sess = tf.Session()\n",
    "\n",
    "print(sess.run(hello))"
   ]
  },
  {
   "cell_type": "code",
   "execution_count": null,
   "outputs": [
    {
     "name": "stderr",
     "output_type": "stream",
     "text": [
      "ERROR:root:Internal Python error in the inspect module.\n",
      "Below is the traceback from this internal error.\n",
      "\n",
      "ERROR:root:Internal Python error in the inspect module.\n",
      "Below is the traceback from this internal error.\n",
      "\n",
      "ERROR:root:Internal Python error in the inspect module.\n",
      "Below is the traceback from this internal error.\n",
      "\n"
     ]
    },
    {
     "name": "stdout",
     "output_type": "stream",
     "text": [
      "ERROR! Session/line number was not unique in database. History logging moved to new session 62\n",
      "Traceback (most recent call last):\n",
      "  File \"/Users/kimyoonseo/opt/anaconda3/envs/myvenv/lib/python3.6/site-packages/IPython/core/interactiveshell.py\", line 3343, in run_code\n",
      "    exec(code_obj, self.user_global_ns, self.user_ns)\n",
      "  File \"<ipython-input-12-148a3cc0aecf>\", line 2, in <module>\n",
      "    node1 = tf.constant(3.0, tf.float32)\n",
      "  File \"/Users/kimyoonseo/opt/anaconda3/envs/myvenv/lib/python3.6/site-packages/tensorflow_core/python/util/module_wrapper.py\", line 193, in __getattr__\n",
      "    set([\n",
      "AttributeError: module 'tensorflow' has no attribute 'constant'\n",
      "\n",
      "During handling of the above exception, another exception occurred:\n",
      "\n",
      "Traceback (most recent call last):\n",
      "  File \"/Users/kimyoonseo/opt/anaconda3/envs/myvenv/lib/python3.6/site-packages/IPython/core/interactiveshell.py\", line 2044, in showtraceback\n",
      "    stb = value._render_traceback_()\n",
      "AttributeError: 'AttributeError' object has no attribute '_render_traceback_'\n",
      "\n",
      "During handling of the above exception, another exception occurred:\n",
      "\n",
      "Traceback (most recent call last):\n",
      "  File \"/Users/kimyoonseo/opt/anaconda3/envs/myvenv/lib/python3.6/site-packages/IPython/core/ultratb.py\", line 1169, in get_records\n",
      "    return _fixed_getinnerframes(etb, number_of_lines_of_context, tb_offset)\n",
      "  File \"/Users/kimyoonseo/opt/anaconda3/envs/myvenv/lib/python3.6/site-packages/IPython/core/ultratb.py\", line 316, in wrapped\n",
      "    return f(*args, **kwargs)\n",
      "  File \"/Users/kimyoonseo/opt/anaconda3/envs/myvenv/lib/python3.6/site-packages/IPython/core/ultratb.py\", line 350, in _fixed_getinnerframes\n",
      "    records = fix_frame_records_filenames(inspect.getinnerframes(etb, context))\n",
      "  File \"/Users/kimyoonseo/opt/anaconda3/envs/myvenv/lib/python3.6/inspect.py\", line 1490, in getinnerframes\n",
      "    frameinfo = (tb.tb_frame,) + getframeinfo(tb, context)\n",
      "  File \"/Users/kimyoonseo/opt/anaconda3/envs/myvenv/lib/python3.6/inspect.py\", line 1448, in getframeinfo\n",
      "    filename = getsourcefile(frame) or getfile(frame)\n",
      "  File \"/Users/kimyoonseo/opt/anaconda3/envs/myvenv/lib/python3.6/inspect.py\", line 696, in getsourcefile\n",
      "    if getattr(getmodule(object, filename), '__loader__', None) is not None:\n",
      "  File \"/Users/kimyoonseo/opt/anaconda3/envs/myvenv/lib/python3.6/inspect.py\", line 733, in getmodule\n",
      "    if ismodule(module) and hasattr(module, '__file__'):\n",
      "  File \"/Users/kimyoonseo/opt/anaconda3/envs/myvenv/lib/python3.6/site-packages/tensorflow/__init__.py\", line 50, in __getattr__\n",
      "    module = self._load()\n",
      "  File \"/Users/kimyoonseo/opt/anaconda3/envs/myvenv/lib/python3.6/site-packages/tensorflow/__init__.py\", line 44, in _load\n",
      "    module = _importlib.import_module(self.__name__)\n",
      "  File \"/Users/kimyoonseo/opt/anaconda3/envs/myvenv/lib/python3.6/importlib/__init__.py\", line 126, in import_module\n",
      "    return _bootstrap._gcd_import(name[level:], package, level)\n",
      "  File \"<frozen importlib._bootstrap>\", line 994, in _gcd_import\n",
      "  File \"<frozen importlib._bootstrap>\", line 971, in _find_and_load\n",
      "  File \"<frozen importlib._bootstrap>\", line 941, in _find_and_load_unlocked\n",
      "  File \"<frozen importlib._bootstrap>\", line 219, in _call_with_frames_removed\n",
      "  File \"<frozen importlib._bootstrap>\", line 994, in _gcd_import\n",
      "  File \"<frozen importlib._bootstrap>\", line 971, in _find_and_load\n",
      "  File \"<frozen importlib._bootstrap>\", line 955, in _find_and_load_unlocked\n",
      "  File \"<frozen importlib._bootstrap>\", line 665, in _load_unlocked\n",
      "  File \"<frozen importlib._bootstrap_external>\", line 678, in exec_module\n",
      "  File \"<frozen importlib._bootstrap>\", line 219, in _call_with_frames_removed\n",
      "  File \"/Users/kimyoonseo/opt/anaconda3/envs/myvenv/lib/python3.6/site-packages/tensorflow_core/__init__.py\", line 42, in <module>\n",
      "    from . _api.v2 import audio\n",
      "  File \"/Users/kimyoonseo/opt/anaconda3/envs/myvenv/lib/python3.6/site-packages/tensorflow_core/_api/v2/audio/__init__.py\", line 10, in <module>\n",
      "    from tensorflow.python.ops.gen_audio_ops import decode_wav\n",
      "  File \"/Users/kimyoonseo/opt/anaconda3/envs/myvenv/lib/python3.6/site-packages/tensorflow_core/python/ops/gen_audio_ops.py\", line 11, in <module>\n",
      "    from tensorflow.python.eager import context as _context\n",
      "  File \"/Users/kimyoonseo/opt/anaconda3/envs/myvenv/lib/python3.6/site-packages/tensorflow_core/python/eager/context.py\", line 29, in <module>\n",
      "    from tensorflow.core.protobuf import config_pb2\n",
      "  File \"/Users/kimyoonseo/opt/anaconda3/envs/myvenv/lib/python3.6/site-packages/tensorflow_core/core/protobuf/config_pb2.py\", line 7, in <module>\n",
      "    from google.protobuf import descriptor as _descriptor\n",
      "ModuleNotFoundError: No module named 'google.protobuf'\n",
      "Traceback (most recent call last):\n",
      "  File \"/Users/kimyoonseo/opt/anaconda3/envs/myvenv/lib/python3.6/site-packages/IPython/core/interactiveshell.py\", line 3343, in run_code\n",
      "    exec(code_obj, self.user_global_ns, self.user_ns)\n",
      "  File \"<ipython-input-12-148a3cc0aecf>\", line 2, in <module>\n",
      "    node1 = tf.constant(3.0, tf.float32)\n",
      "  File \"/Users/kimyoonseo/opt/anaconda3/envs/myvenv/lib/python3.6/site-packages/tensorflow_core/python/util/module_wrapper.py\", line 193, in __getattr__\n",
      "    set([\n",
      "AttributeError: module 'tensorflow' has no attribute 'constant'\n",
      "\n",
      "During handling of the above exception, another exception occurred:\n",
      "\n",
      "Traceback (most recent call last):\n",
      "  File \"/Users/kimyoonseo/opt/anaconda3/envs/myvenv/lib/python3.6/site-packages/IPython/core/interactiveshell.py\", line 2044, in showtraceback\n",
      "    stb = value._render_traceback_()\n",
      "AttributeError: 'AttributeError' object has no attribute '_render_traceback_'\n",
      "\n",
      "During handling of the above exception, another exception occurred:\n",
      "\n",
      "Traceback (most recent call last):\n",
      "  File \"/Users/kimyoonseo/opt/anaconda3/envs/myvenv/lib/python3.6/site-packages/IPython/core/interactiveshell.py\", line 3263, in run_ast_nodes\n",
      "    if (await self.run_code(code, result,  async_=asy)):\n",
      "  File \"/Users/kimyoonseo/opt/anaconda3/envs/myvenv/lib/python3.6/site-packages/IPython/core/interactiveshell.py\", line 3360, in run_code\n",
      "    self.showtraceback(running_compiled_code=True)\n",
      "  File \"/Users/kimyoonseo/opt/anaconda3/envs/myvenv/lib/python3.6/site-packages/IPython/core/interactiveshell.py\", line 2047, in showtraceback\n",
      "    value, tb, tb_offset=tb_offset)\n",
      "  File \"/Users/kimyoonseo/opt/anaconda3/envs/myvenv/lib/python3.6/site-packages/IPython/core/ultratb.py\", line 1436, in structured_traceback\n",
      "    self, etype, value, tb, tb_offset, number_of_lines_of_context)\n",
      "  File \"/Users/kimyoonseo/opt/anaconda3/envs/myvenv/lib/python3.6/site-packages/IPython/core/ultratb.py\", line 1336, in structured_traceback\n",
      "    self, etype, value, tb, tb_offset, number_of_lines_of_context\n",
      "  File \"/Users/kimyoonseo/opt/anaconda3/envs/myvenv/lib/python3.6/site-packages/IPython/core/ultratb.py\", line 1193, in structured_traceback\n",
      "    tb_offset)\n",
      "  File \"/Users/kimyoonseo/opt/anaconda3/envs/myvenv/lib/python3.6/site-packages/IPython/core/ultratb.py\", line 1150, in format_exception_as_a_whole\n",
      "    last_unique, recursion_repeat = find_recursion(orig_etype, evalue, records)\n",
      "  File \"/Users/kimyoonseo/opt/anaconda3/envs/myvenv/lib/python3.6/site-packages/IPython/core/ultratb.py\", line 451, in find_recursion\n",
      "    return len(records), 0\n",
      "TypeError: object of type 'NoneType' has no len()\n",
      "\n",
      "During handling of the above exception, another exception occurred:\n",
      "\n",
      "Traceback (most recent call last):\n",
      "  File \"/Users/kimyoonseo/opt/anaconda3/envs/myvenv/lib/python3.6/site-packages/IPython/core/interactiveshell.py\", line 2044, in showtraceback\n",
      "    stb = value._render_traceback_()\n",
      "AttributeError: 'TypeError' object has no attribute '_render_traceback_'\n",
      "\n",
      "During handling of the above exception, another exception occurred:\n",
      "\n",
      "Traceback (most recent call last):\n",
      "  File \"/Users/kimyoonseo/opt/anaconda3/envs/myvenv/lib/python3.6/site-packages/IPython/core/ultratb.py\", line 1169, in get_records\n",
      "    return _fixed_getinnerframes(etb, number_of_lines_of_context, tb_offset)\n",
      "  File \"/Users/kimyoonseo/opt/anaconda3/envs/myvenv/lib/python3.6/site-packages/IPython/core/ultratb.py\", line 316, in wrapped\n",
      "    return f(*args, **kwargs)\n",
      "  File \"/Users/kimyoonseo/opt/anaconda3/envs/myvenv/lib/python3.6/site-packages/IPython/core/ultratb.py\", line 350, in _fixed_getinnerframes\n",
      "    records = fix_frame_records_filenames(inspect.getinnerframes(etb, context))\n",
      "  File \"/Users/kimyoonseo/opt/anaconda3/envs/myvenv/lib/python3.6/inspect.py\", line 1490, in getinnerframes\n",
      "    frameinfo = (tb.tb_frame,) + getframeinfo(tb, context)\n",
      "  File \"/Users/kimyoonseo/opt/anaconda3/envs/myvenv/lib/python3.6/inspect.py\", line 1448, in getframeinfo\n",
      "    filename = getsourcefile(frame) or getfile(frame)\n",
      "  File \"/Users/kimyoonseo/opt/anaconda3/envs/myvenv/lib/python3.6/inspect.py\", line 696, in getsourcefile\n",
      "    if getattr(getmodule(object, filename), '__loader__', None) is not None:\n",
      "  File \"/Users/kimyoonseo/opt/anaconda3/envs/myvenv/lib/python3.6/inspect.py\", line 733, in getmodule\n",
      "    if ismodule(module) and hasattr(module, '__file__'):\n",
      "  File \"/Users/kimyoonseo/opt/anaconda3/envs/myvenv/lib/python3.6/site-packages/tensorflow/__init__.py\", line 50, in __getattr__\n",
      "    module = self._load()\n",
      "  File \"/Users/kimyoonseo/opt/anaconda3/envs/myvenv/lib/python3.6/site-packages/tensorflow/__init__.py\", line 44, in _load\n",
      "    module = _importlib.import_module(self.__name__)\n",
      "  File \"/Users/kimyoonseo/opt/anaconda3/envs/myvenv/lib/python3.6/importlib/__init__.py\", line 126, in import_module\n",
      "    return _bootstrap._gcd_import(name[level:], package, level)\n",
      "  File \"<frozen importlib._bootstrap>\", line 994, in _gcd_import\n",
      "  File \"<frozen importlib._bootstrap>\", line 971, in _find_and_load\n",
      "  File \"<frozen importlib._bootstrap>\", line 941, in _find_and_load_unlocked\n",
      "  File \"<frozen importlib._bootstrap>\", line 219, in _call_with_frames_removed\n",
      "  File \"<frozen importlib._bootstrap>\", line 994, in _gcd_import\n",
      "  File \"<frozen importlib._bootstrap>\", line 971, in _find_and_load\n",
      "  File \"<frozen importlib._bootstrap>\", line 955, in _find_and_load_unlocked\n",
      "  File \"<frozen importlib._bootstrap>\", line 665, in _load_unlocked\n",
      "  File \"<frozen importlib._bootstrap_external>\", line 678, in exec_module\n",
      "  File \"<frozen importlib._bootstrap>\", line 219, in _call_with_frames_removed\n",
      "  File \"/Users/kimyoonseo/opt/anaconda3/envs/myvenv/lib/python3.6/site-packages/tensorflow_core/__init__.py\", line 42, in <module>\n",
      "    from . _api.v2 import audio\n",
      "  File \"/Users/kimyoonseo/opt/anaconda3/envs/myvenv/lib/python3.6/site-packages/tensorflow_core/_api/v2/audio/__init__.py\", line 10, in <module>\n",
      "    from tensorflow.python.ops.gen_audio_ops import decode_wav\n",
      "  File \"/Users/kimyoonseo/opt/anaconda3/envs/myvenv/lib/python3.6/site-packages/tensorflow_core/python/ops/gen_audio_ops.py\", line 11, in <module>\n",
      "    from tensorflow.python.eager import context as _context\n",
      "  File \"/Users/kimyoonseo/opt/anaconda3/envs/myvenv/lib/python3.6/site-packages/tensorflow_core/python/eager/context.py\", line 29, in <module>\n",
      "    from tensorflow.core.protobuf import config_pb2\n",
      "  File \"/Users/kimyoonseo/opt/anaconda3/envs/myvenv/lib/python3.6/site-packages/tensorflow_core/core/protobuf/config_pb2.py\", line 7, in <module>\n",
      "    from google.protobuf import descriptor as _descriptor\n",
      "ModuleNotFoundError: No module named 'google.protobuf'\n",
      "Traceback (most recent call last):\n",
      "  File \"/Users/kimyoonseo/opt/anaconda3/envs/myvenv/lib/python3.6/site-packages/IPython/core/interactiveshell.py\", line 3343, in run_code\n",
      "    exec(code_obj, self.user_global_ns, self.user_ns)\n",
      "  File \"<ipython-input-12-148a3cc0aecf>\", line 2, in <module>\n",
      "    node1 = tf.constant(3.0, tf.float32)\n",
      "  File \"/Users/kimyoonseo/opt/anaconda3/envs/myvenv/lib/python3.6/site-packages/tensorflow_core/python/util/module_wrapper.py\", line 193, in __getattr__\n",
      "    set([\n",
      "AttributeError: module 'tensorflow' has no attribute 'constant'\n",
      "\n",
      "During handling of the above exception, another exception occurred:\n",
      "\n",
      "Traceback (most recent call last):\n",
      "  File \"/Users/kimyoonseo/opt/anaconda3/envs/myvenv/lib/python3.6/site-packages/IPython/core/interactiveshell.py\", line 2044, in showtraceback\n",
      "    stb = value._render_traceback_()\n",
      "AttributeError: 'AttributeError' object has no attribute '_render_traceback_'\n",
      "\n",
      "During handling of the above exception, another exception occurred:\n",
      "\n",
      "Traceback (most recent call last):\n",
      "  File \"/Users/kimyoonseo/opt/anaconda3/envs/myvenv/lib/python3.6/site-packages/IPython/core/interactiveshell.py\", line 3263, in run_ast_nodes\n",
      "    if (await self.run_code(code, result,  async_=asy)):\n",
      "  File \"/Users/kimyoonseo/opt/anaconda3/envs/myvenv/lib/python3.6/site-packages/IPython/core/interactiveshell.py\", line 3360, in run_code\n",
      "    self.showtraceback(running_compiled_code=True)\n",
      "  File \"/Users/kimyoonseo/opt/anaconda3/envs/myvenv/lib/python3.6/site-packages/IPython/core/interactiveshell.py\", line 2047, in showtraceback\n",
      "    value, tb, tb_offset=tb_offset)\n",
      "  File \"/Users/kimyoonseo/opt/anaconda3/envs/myvenv/lib/python3.6/site-packages/IPython/core/ultratb.py\", line 1436, in structured_traceback\n",
      "    self, etype, value, tb, tb_offset, number_of_lines_of_context)\n",
      "  File \"/Users/kimyoonseo/opt/anaconda3/envs/myvenv/lib/python3.6/site-packages/IPython/core/ultratb.py\", line 1336, in structured_traceback\n",
      "    self, etype, value, tb, tb_offset, number_of_lines_of_context\n",
      "  File \"/Users/kimyoonseo/opt/anaconda3/envs/myvenv/lib/python3.6/site-packages/IPython/core/ultratb.py\", line 1193, in structured_traceback\n",
      "    tb_offset)\n",
      "  File \"/Users/kimyoonseo/opt/anaconda3/envs/myvenv/lib/python3.6/site-packages/IPython/core/ultratb.py\", line 1150, in format_exception_as_a_whole\n",
      "    last_unique, recursion_repeat = find_recursion(orig_etype, evalue, records)\n",
      "  File \"/Users/kimyoonseo/opt/anaconda3/envs/myvenv/lib/python3.6/site-packages/IPython/core/ultratb.py\", line 451, in find_recursion\n",
      "    return len(records), 0\n",
      "TypeError: object of type 'NoneType' has no len()\n",
      "\n",
      "During handling of the above exception, another exception occurred:\n",
      "\n",
      "Traceback (most recent call last):\n",
      "  File \"/Users/kimyoonseo/opt/anaconda3/envs/myvenv/lib/python3.6/site-packages/IPython/core/interactiveshell.py\", line 2044, in showtraceback\n",
      "    stb = value._render_traceback_()\n",
      "AttributeError: 'TypeError' object has no attribute '_render_traceback_'\n",
      "\n",
      "During handling of the above exception, another exception occurred:\n",
      "\n",
      "Traceback (most recent call last):\n",
      "  File \"/Users/kimyoonseo/opt/anaconda3/envs/myvenv/lib/python3.6/site-packages/IPython/core/interactiveshell.py\", line 2895, in _run_cell\n",
      "    return runner(coro)\n",
      "  File \"/Users/kimyoonseo/opt/anaconda3/envs/myvenv/lib/python3.6/site-packages/IPython/core/async_helpers.py\", line 68, in _pseudo_sync_runner\n",
      "    coro.send(None)\n",
      "  File \"/Users/kimyoonseo/opt/anaconda3/envs/myvenv/lib/python3.6/site-packages/IPython/core/interactiveshell.py\", line 3072, in run_cell_async\n",
      "    interactivity=interactivity, compiler=compiler, result=result)\n",
      "  File \"/Users/kimyoonseo/opt/anaconda3/envs/myvenv/lib/python3.6/site-packages/IPython/core/interactiveshell.py\", line 3282, in run_ast_nodes\n",
      "    self.showtraceback()\n",
      "  File \"/Users/kimyoonseo/opt/anaconda3/envs/myvenv/lib/python3.6/site-packages/IPython/core/interactiveshell.py\", line 2047, in showtraceback\n",
      "    value, tb, tb_offset=tb_offset)\n",
      "  File \"/Users/kimyoonseo/opt/anaconda3/envs/myvenv/lib/python3.6/site-packages/IPython/core/ultratb.py\", line 1436, in structured_traceback\n",
      "    self, etype, value, tb, tb_offset, number_of_lines_of_context)\n",
      "  File \"/Users/kimyoonseo/opt/anaconda3/envs/myvenv/lib/python3.6/site-packages/IPython/core/ultratb.py\", line 1336, in structured_traceback\n",
      "    self, etype, value, tb, tb_offset, number_of_lines_of_context\n",
      "  File \"/Users/kimyoonseo/opt/anaconda3/envs/myvenv/lib/python3.6/site-packages/IPython/core/ultratb.py\", line 1211, in structured_traceback\n",
      "    chained_exceptions_tb_offset)\n",
      "  File \"/Users/kimyoonseo/opt/anaconda3/envs/myvenv/lib/python3.6/site-packages/IPython/core/ultratb.py\", line 1150, in format_exception_as_a_whole\n",
      "    last_unique, recursion_repeat = find_recursion(orig_etype, evalue, records)\n",
      "  File \"/Users/kimyoonseo/opt/anaconda3/envs/myvenv/lib/python3.6/site-packages/IPython/core/ultratb.py\", line 451, in find_recursion\n",
      "    return len(records), 0\n",
      "TypeError: object of type 'NoneType' has no len()\n",
      "\n",
      "During handling of the above exception, another exception occurred:\n",
      "\n",
      "Traceback (most recent call last):\n",
      "  File \"/Users/kimyoonseo/opt/anaconda3/envs/myvenv/lib/python3.6/site-packages/IPython/core/interactiveshell.py\", line 2044, in showtraceback\n",
      "    stb = value._render_traceback_()\n",
      "AttributeError: 'TypeError' object has no attribute '_render_traceback_'\n",
      "\n",
      "During handling of the above exception, another exception occurred:\n",
      "\n",
      "Traceback (most recent call last):\n",
      "  File \"/Users/kimyoonseo/opt/anaconda3/envs/myvenv/lib/python3.6/site-packages/IPython/core/ultratb.py\", line 1169, in get_records\n",
      "    return _fixed_getinnerframes(etb, number_of_lines_of_context, tb_offset)\n",
      "  File \"/Users/kimyoonseo/opt/anaconda3/envs/myvenv/lib/python3.6/site-packages/IPython/core/ultratb.py\", line 316, in wrapped\n",
      "    return f(*args, **kwargs)\n",
      "  File \"/Users/kimyoonseo/opt/anaconda3/envs/myvenv/lib/python3.6/site-packages/IPython/core/ultratb.py\", line 350, in _fixed_getinnerframes\n",
      "    records = fix_frame_records_filenames(inspect.getinnerframes(etb, context))\n",
      "  File \"/Users/kimyoonseo/opt/anaconda3/envs/myvenv/lib/python3.6/inspect.py\", line 1490, in getinnerframes\n",
      "    frameinfo = (tb.tb_frame,) + getframeinfo(tb, context)\n",
      "  File \"/Users/kimyoonseo/opt/anaconda3/envs/myvenv/lib/python3.6/inspect.py\", line 1448, in getframeinfo\n",
      "    filename = getsourcefile(frame) or getfile(frame)\n",
      "  File \"/Users/kimyoonseo/opt/anaconda3/envs/myvenv/lib/python3.6/inspect.py\", line 696, in getsourcefile\n",
      "    if getattr(getmodule(object, filename), '__loader__', None) is not None:\n",
      "  File \"/Users/kimyoonseo/opt/anaconda3/envs/myvenv/lib/python3.6/inspect.py\", line 733, in getmodule\n",
      "    if ismodule(module) and hasattr(module, '__file__'):\n",
      "  File \"/Users/kimyoonseo/opt/anaconda3/envs/myvenv/lib/python3.6/site-packages/tensorflow/__init__.py\", line 50, in __getattr__\n",
      "    module = self._load()\n",
      "  File \"/Users/kimyoonseo/opt/anaconda3/envs/myvenv/lib/python3.6/site-packages/tensorflow/__init__.py\", line 44, in _load\n",
      "    module = _importlib.import_module(self.__name__)\n",
      "  File \"/Users/kimyoonseo/opt/anaconda3/envs/myvenv/lib/python3.6/importlib/__init__.py\", line 126, in import_module\n",
      "    return _bootstrap._gcd_import(name[level:], package, level)\n",
      "  File \"<frozen importlib._bootstrap>\", line 994, in _gcd_import\n",
      "  File \"<frozen importlib._bootstrap>\", line 971, in _find_and_load\n",
      "  File \"<frozen importlib._bootstrap>\", line 941, in _find_and_load_unlocked\n",
      "  File \"<frozen importlib._bootstrap>\", line 219, in _call_with_frames_removed\n",
      "  File \"<frozen importlib._bootstrap>\", line 994, in _gcd_import\n",
      "  File \"<frozen importlib._bootstrap>\", line 971, in _find_and_load\n",
      "  File \"<frozen importlib._bootstrap>\", line 955, in _find_and_load_unlocked\n",
      "  File \"<frozen importlib._bootstrap>\", line 665, in _load_unlocked\n",
      "  File \"<frozen importlib._bootstrap_external>\", line 678, in exec_module\n",
      "  File \"<frozen importlib._bootstrap>\", line 219, in _call_with_frames_removed\n",
      "  File \"/Users/kimyoonseo/opt/anaconda3/envs/myvenv/lib/python3.6/site-packages/tensorflow_core/__init__.py\", line 42, in <module>\n",
      "    from . _api.v2 import audio\n",
      "  File \"/Users/kimyoonseo/opt/anaconda3/envs/myvenv/lib/python3.6/site-packages/tensorflow_core/_api/v2/audio/__init__.py\", line 10, in <module>\n",
      "    from tensorflow.python.ops.gen_audio_ops import decode_wav\n",
      "  File \"/Users/kimyoonseo/opt/anaconda3/envs/myvenv/lib/python3.6/site-packages/tensorflow_core/python/ops/gen_audio_ops.py\", line 11, in <module>\n",
      "    from tensorflow.python.eager import context as _context\n",
      "  File \"/Users/kimyoonseo/opt/anaconda3/envs/myvenv/lib/python3.6/site-packages/tensorflow_core/python/eager/context.py\", line 29, in <module>\n",
      "    from tensorflow.core.protobuf import config_pb2\n",
      "  File \"/Users/kimyoonseo/opt/anaconda3/envs/myvenv/lib/python3.6/site-packages/tensorflow_core/core/protobuf/config_pb2.py\", line 7, in <module>\n",
      "    from google.protobuf import descriptor as _descriptor\n",
      "ModuleNotFoundError: No module named 'google.protobuf'\n"
     ]
    }
   ],
   "source": [
    "# 그래프 빌드\n",
    "node1 = tf.constant(3.0, tf.float32)\n",
    "node2 = tf.constant(4.0,)\n",
    "node3 = tf.add(node1, node2)\n",
    "\n",
    "# 그래프의 하나의 요소인 것만 리턴 (= tensor)\n",
    "print(\"node1: \", node1, \"node2: \", node2)\n",
    "print(\"node3: \", node3)"
   ],
   "metadata": {
    "collapsed": false,
    "pycharm": {
     "name": "#%%\n",
     "is_executing": true
    }
   }
  },
  {
   "cell_type": "code",
   "execution_count": null,
   "outputs": [
    {
     "name": "stderr",
     "output_type": "stream",
     "text": [
      "ERROR:root:Internal Python error in the inspect module.\n",
      "Below is the traceback from this internal error.\n",
      "\n",
      "ERROR:root:Internal Python error in the inspect module.\n",
      "Below is the traceback from this internal error.\n",
      "\n",
      "ERROR:root:Internal Python error in the inspect module.\n",
      "Below is the traceback from this internal error.\n",
      "\n"
     ]
    },
    {
     "name": "stdout",
     "output_type": "stream",
     "text": [
      "ERROR! Session/line number was not unique in database. History logging moved to new session 63\n",
      "Traceback (most recent call last):\n",
      "  File \"/Users/kimyoonseo/opt/anaconda3/envs/myvenv/lib/python3.6/site-packages/IPython/core/interactiveshell.py\", line 3343, in run_code\n",
      "    exec(code_obj, self.user_global_ns, self.user_ns)\n",
      "  File \"<ipython-input-12-092a6edb2289>\", line 2, in <module>\n",
      "    sess = tf.Session()\n",
      "  File \"/Users/kimyoonseo/opt/anaconda3/envs/myvenv/lib/python3.6/site-packages/tensorflow_core/python/util/module_wrapper.py\", line 193, in __getattr__\n",
      "    set([\n",
      "AttributeError: module 'tensorflow' has no attribute 'Session'\n",
      "\n",
      "During handling of the above exception, another exception occurred:\n",
      "\n",
      "Traceback (most recent call last):\n",
      "  File \"/Users/kimyoonseo/opt/anaconda3/envs/myvenv/lib/python3.6/site-packages/IPython/core/interactiveshell.py\", line 2044, in showtraceback\n",
      "    stb = value._render_traceback_()\n",
      "AttributeError: 'AttributeError' object has no attribute '_render_traceback_'\n",
      "\n",
      "During handling of the above exception, another exception occurred:\n",
      "\n",
      "Traceback (most recent call last):\n",
      "  File \"/Users/kimyoonseo/opt/anaconda3/envs/myvenv/lib/python3.6/site-packages/IPython/core/ultratb.py\", line 1169, in get_records\n",
      "    return _fixed_getinnerframes(etb, number_of_lines_of_context, tb_offset)\n",
      "  File \"/Users/kimyoonseo/opt/anaconda3/envs/myvenv/lib/python3.6/site-packages/IPython/core/ultratb.py\", line 316, in wrapped\n",
      "    return f(*args, **kwargs)\n",
      "  File \"/Users/kimyoonseo/opt/anaconda3/envs/myvenv/lib/python3.6/site-packages/IPython/core/ultratb.py\", line 350, in _fixed_getinnerframes\n",
      "    records = fix_frame_records_filenames(inspect.getinnerframes(etb, context))\n",
      "  File \"/Users/kimyoonseo/opt/anaconda3/envs/myvenv/lib/python3.6/inspect.py\", line 1490, in getinnerframes\n",
      "    frameinfo = (tb.tb_frame,) + getframeinfo(tb, context)\n",
      "  File \"/Users/kimyoonseo/opt/anaconda3/envs/myvenv/lib/python3.6/inspect.py\", line 1448, in getframeinfo\n",
      "    filename = getsourcefile(frame) or getfile(frame)\n",
      "  File \"/Users/kimyoonseo/opt/anaconda3/envs/myvenv/lib/python3.6/inspect.py\", line 696, in getsourcefile\n",
      "    if getattr(getmodule(object, filename), '__loader__', None) is not None:\n",
      "  File \"/Users/kimyoonseo/opt/anaconda3/envs/myvenv/lib/python3.6/inspect.py\", line 733, in getmodule\n",
      "    if ismodule(module) and hasattr(module, '__file__'):\n",
      "  File \"/Users/kimyoonseo/opt/anaconda3/envs/myvenv/lib/python3.6/site-packages/tensorflow/__init__.py\", line 50, in __getattr__\n",
      "    module = self._load()\n",
      "  File \"/Users/kimyoonseo/opt/anaconda3/envs/myvenv/lib/python3.6/site-packages/tensorflow/__init__.py\", line 44, in _load\n",
      "    module = _importlib.import_module(self.__name__)\n",
      "  File \"/Users/kimyoonseo/opt/anaconda3/envs/myvenv/lib/python3.6/importlib/__init__.py\", line 126, in import_module\n",
      "    return _bootstrap._gcd_import(name[level:], package, level)\n",
      "  File \"<frozen importlib._bootstrap>\", line 994, in _gcd_import\n",
      "  File \"<frozen importlib._bootstrap>\", line 971, in _find_and_load\n",
      "  File \"<frozen importlib._bootstrap>\", line 941, in _find_and_load_unlocked\n",
      "  File \"<frozen importlib._bootstrap>\", line 219, in _call_with_frames_removed\n",
      "  File \"<frozen importlib._bootstrap>\", line 994, in _gcd_import\n",
      "  File \"<frozen importlib._bootstrap>\", line 971, in _find_and_load\n",
      "  File \"<frozen importlib._bootstrap>\", line 955, in _find_and_load_unlocked\n",
      "  File \"<frozen importlib._bootstrap>\", line 665, in _load_unlocked\n",
      "  File \"<frozen importlib._bootstrap_external>\", line 678, in exec_module\n",
      "  File \"<frozen importlib._bootstrap>\", line 219, in _call_with_frames_removed\n",
      "  File \"/Users/kimyoonseo/opt/anaconda3/envs/myvenv/lib/python3.6/site-packages/tensorflow_core/__init__.py\", line 42, in <module>\n",
      "    from . _api.v2 import audio\n",
      "  File \"/Users/kimyoonseo/opt/anaconda3/envs/myvenv/lib/python3.6/site-packages/tensorflow_core/_api/v2/audio/__init__.py\", line 10, in <module>\n",
      "    from tensorflow.python.ops.gen_audio_ops import decode_wav\n",
      "  File \"/Users/kimyoonseo/opt/anaconda3/envs/myvenv/lib/python3.6/site-packages/tensorflow_core/python/ops/gen_audio_ops.py\", line 11, in <module>\n",
      "    from tensorflow.python.eager import context as _context\n",
      "  File \"/Users/kimyoonseo/opt/anaconda3/envs/myvenv/lib/python3.6/site-packages/tensorflow_core/python/eager/context.py\", line 29, in <module>\n",
      "    from tensorflow.core.protobuf import config_pb2\n",
      "  File \"/Users/kimyoonseo/opt/anaconda3/envs/myvenv/lib/python3.6/site-packages/tensorflow_core/core/protobuf/config_pb2.py\", line 7, in <module>\n",
      "    from google.protobuf import descriptor as _descriptor\n",
      "ModuleNotFoundError: No module named 'google.protobuf'\n",
      "Traceback (most recent call last):\n",
      "  File \"/Users/kimyoonseo/opt/anaconda3/envs/myvenv/lib/python3.6/site-packages/IPython/core/interactiveshell.py\", line 3343, in run_code\n",
      "    exec(code_obj, self.user_global_ns, self.user_ns)\n",
      "  File \"<ipython-input-12-092a6edb2289>\", line 2, in <module>\n",
      "    sess = tf.Session()\n",
      "  File \"/Users/kimyoonseo/opt/anaconda3/envs/myvenv/lib/python3.6/site-packages/tensorflow_core/python/util/module_wrapper.py\", line 193, in __getattr__\n",
      "    set([\n",
      "AttributeError: module 'tensorflow' has no attribute 'Session'\n",
      "\n",
      "During handling of the above exception, another exception occurred:\n",
      "\n",
      "Traceback (most recent call last):\n",
      "  File \"/Users/kimyoonseo/opt/anaconda3/envs/myvenv/lib/python3.6/site-packages/IPython/core/interactiveshell.py\", line 2044, in showtraceback\n",
      "    stb = value._render_traceback_()\n",
      "AttributeError: 'AttributeError' object has no attribute '_render_traceback_'\n",
      "\n",
      "During handling of the above exception, another exception occurred:\n",
      "\n",
      "Traceback (most recent call last):\n",
      "  File \"/Users/kimyoonseo/opt/anaconda3/envs/myvenv/lib/python3.6/site-packages/IPython/core/interactiveshell.py\", line 3263, in run_ast_nodes\n",
      "    if (await self.run_code(code, result,  async_=asy)):\n",
      "  File \"/Users/kimyoonseo/opt/anaconda3/envs/myvenv/lib/python3.6/site-packages/IPython/core/interactiveshell.py\", line 3360, in run_code\n",
      "    self.showtraceback(running_compiled_code=True)\n",
      "  File \"/Users/kimyoonseo/opt/anaconda3/envs/myvenv/lib/python3.6/site-packages/IPython/core/interactiveshell.py\", line 2047, in showtraceback\n",
      "    value, tb, tb_offset=tb_offset)\n",
      "  File \"/Users/kimyoonseo/opt/anaconda3/envs/myvenv/lib/python3.6/site-packages/IPython/core/ultratb.py\", line 1436, in structured_traceback\n",
      "    self, etype, value, tb, tb_offset, number_of_lines_of_context)\n",
      "  File \"/Users/kimyoonseo/opt/anaconda3/envs/myvenv/lib/python3.6/site-packages/IPython/core/ultratb.py\", line 1336, in structured_traceback\n",
      "    self, etype, value, tb, tb_offset, number_of_lines_of_context\n",
      "  File \"/Users/kimyoonseo/opt/anaconda3/envs/myvenv/lib/python3.6/site-packages/IPython/core/ultratb.py\", line 1193, in structured_traceback\n",
      "    tb_offset)\n",
      "  File \"/Users/kimyoonseo/opt/anaconda3/envs/myvenv/lib/python3.6/site-packages/IPython/core/ultratb.py\", line 1150, in format_exception_as_a_whole\n",
      "    last_unique, recursion_repeat = find_recursion(orig_etype, evalue, records)\n",
      "  File \"/Users/kimyoonseo/opt/anaconda3/envs/myvenv/lib/python3.6/site-packages/IPython/core/ultratb.py\", line 451, in find_recursion\n",
      "    return len(records), 0\n",
      "TypeError: object of type 'NoneType' has no len()\n",
      "\n",
      "During handling of the above exception, another exception occurred:\n",
      "\n",
      "Traceback (most recent call last):\n",
      "  File \"/Users/kimyoonseo/opt/anaconda3/envs/myvenv/lib/python3.6/site-packages/IPython/core/interactiveshell.py\", line 2044, in showtraceback\n",
      "    stb = value._render_traceback_()\n",
      "AttributeError: 'TypeError' object has no attribute '_render_traceback_'\n",
      "\n",
      "During handling of the above exception, another exception occurred:\n",
      "\n",
      "Traceback (most recent call last):\n",
      "  File \"/Users/kimyoonseo/opt/anaconda3/envs/myvenv/lib/python3.6/site-packages/IPython/core/ultratb.py\", line 1169, in get_records\n",
      "    return _fixed_getinnerframes(etb, number_of_lines_of_context, tb_offset)\n",
      "  File \"/Users/kimyoonseo/opt/anaconda3/envs/myvenv/lib/python3.6/site-packages/IPython/core/ultratb.py\", line 316, in wrapped\n",
      "    return f(*args, **kwargs)\n",
      "  File \"/Users/kimyoonseo/opt/anaconda3/envs/myvenv/lib/python3.6/site-packages/IPython/core/ultratb.py\", line 350, in _fixed_getinnerframes\n",
      "    records = fix_frame_records_filenames(inspect.getinnerframes(etb, context))\n",
      "  File \"/Users/kimyoonseo/opt/anaconda3/envs/myvenv/lib/python3.6/inspect.py\", line 1490, in getinnerframes\n",
      "    frameinfo = (tb.tb_frame,) + getframeinfo(tb, context)\n",
      "  File \"/Users/kimyoonseo/opt/anaconda3/envs/myvenv/lib/python3.6/inspect.py\", line 1448, in getframeinfo\n",
      "    filename = getsourcefile(frame) or getfile(frame)\n",
      "  File \"/Users/kimyoonseo/opt/anaconda3/envs/myvenv/lib/python3.6/inspect.py\", line 696, in getsourcefile\n",
      "    if getattr(getmodule(object, filename), '__loader__', None) is not None:\n",
      "  File \"/Users/kimyoonseo/opt/anaconda3/envs/myvenv/lib/python3.6/inspect.py\", line 733, in getmodule\n",
      "    if ismodule(module) and hasattr(module, '__file__'):\n",
      "  File \"/Users/kimyoonseo/opt/anaconda3/envs/myvenv/lib/python3.6/site-packages/tensorflow/__init__.py\", line 50, in __getattr__\n",
      "    module = self._load()\n",
      "  File \"/Users/kimyoonseo/opt/anaconda3/envs/myvenv/lib/python3.6/site-packages/tensorflow/__init__.py\", line 44, in _load\n",
      "    module = _importlib.import_module(self.__name__)\n",
      "  File \"/Users/kimyoonseo/opt/anaconda3/envs/myvenv/lib/python3.6/importlib/__init__.py\", line 126, in import_module\n",
      "    return _bootstrap._gcd_import(name[level:], package, level)\n",
      "  File \"<frozen importlib._bootstrap>\", line 994, in _gcd_import\n",
      "  File \"<frozen importlib._bootstrap>\", line 971, in _find_and_load\n",
      "  File \"<frozen importlib._bootstrap>\", line 941, in _find_and_load_unlocked\n",
      "  File \"<frozen importlib._bootstrap>\", line 219, in _call_with_frames_removed\n",
      "  File \"<frozen importlib._bootstrap>\", line 994, in _gcd_import\n",
      "  File \"<frozen importlib._bootstrap>\", line 971, in _find_and_load\n",
      "  File \"<frozen importlib._bootstrap>\", line 955, in _find_and_load_unlocked\n",
      "  File \"<frozen importlib._bootstrap>\", line 665, in _load_unlocked\n",
      "  File \"<frozen importlib._bootstrap_external>\", line 678, in exec_module\n",
      "  File \"<frozen importlib._bootstrap>\", line 219, in _call_with_frames_removed\n",
      "  File \"/Users/kimyoonseo/opt/anaconda3/envs/myvenv/lib/python3.6/site-packages/tensorflow_core/__init__.py\", line 42, in <module>\n",
      "    from . _api.v2 import audio\n",
      "  File \"/Users/kimyoonseo/opt/anaconda3/envs/myvenv/lib/python3.6/site-packages/tensorflow_core/_api/v2/audio/__init__.py\", line 10, in <module>\n",
      "    from tensorflow.python.ops.gen_audio_ops import decode_wav\n",
      "  File \"/Users/kimyoonseo/opt/anaconda3/envs/myvenv/lib/python3.6/site-packages/tensorflow_core/python/ops/gen_audio_ops.py\", line 11, in <module>\n",
      "    from tensorflow.python.eager import context as _context\n",
      "  File \"/Users/kimyoonseo/opt/anaconda3/envs/myvenv/lib/python3.6/site-packages/tensorflow_core/python/eager/context.py\", line 29, in <module>\n",
      "    from tensorflow.core.protobuf import config_pb2\n",
      "  File \"/Users/kimyoonseo/opt/anaconda3/envs/myvenv/lib/python3.6/site-packages/tensorflow_core/core/protobuf/config_pb2.py\", line 7, in <module>\n",
      "    from google.protobuf import descriptor as _descriptor\n",
      "ModuleNotFoundError: No module named 'google.protobuf'\n",
      "Traceback (most recent call last):\n",
      "  File \"/Users/kimyoonseo/opt/anaconda3/envs/myvenv/lib/python3.6/site-packages/IPython/core/interactiveshell.py\", line 3343, in run_code\n",
      "    exec(code_obj, self.user_global_ns, self.user_ns)\n",
      "  File \"<ipython-input-12-092a6edb2289>\", line 2, in <module>\n",
      "    sess = tf.Session()\n",
      "  File \"/Users/kimyoonseo/opt/anaconda3/envs/myvenv/lib/python3.6/site-packages/tensorflow_core/python/util/module_wrapper.py\", line 193, in __getattr__\n",
      "    set([\n",
      "AttributeError: module 'tensorflow' has no attribute 'Session'\n",
      "\n",
      "During handling of the above exception, another exception occurred:\n",
      "\n",
      "Traceback (most recent call last):\n",
      "  File \"/Users/kimyoonseo/opt/anaconda3/envs/myvenv/lib/python3.6/site-packages/IPython/core/interactiveshell.py\", line 2044, in showtraceback\n",
      "    stb = value._render_traceback_()\n",
      "AttributeError: 'AttributeError' object has no attribute '_render_traceback_'\n",
      "\n",
      "During handling of the above exception, another exception occurred:\n",
      "\n",
      "Traceback (most recent call last):\n",
      "  File \"/Users/kimyoonseo/opt/anaconda3/envs/myvenv/lib/python3.6/site-packages/IPython/core/interactiveshell.py\", line 3263, in run_ast_nodes\n",
      "    if (await self.run_code(code, result,  async_=asy)):\n",
      "  File \"/Users/kimyoonseo/opt/anaconda3/envs/myvenv/lib/python3.6/site-packages/IPython/core/interactiveshell.py\", line 3360, in run_code\n",
      "    self.showtraceback(running_compiled_code=True)\n",
      "  File \"/Users/kimyoonseo/opt/anaconda3/envs/myvenv/lib/python3.6/site-packages/IPython/core/interactiveshell.py\", line 2047, in showtraceback\n",
      "    value, tb, tb_offset=tb_offset)\n",
      "  File \"/Users/kimyoonseo/opt/anaconda3/envs/myvenv/lib/python3.6/site-packages/IPython/core/ultratb.py\", line 1436, in structured_traceback\n",
      "    self, etype, value, tb, tb_offset, number_of_lines_of_context)\n",
      "  File \"/Users/kimyoonseo/opt/anaconda3/envs/myvenv/lib/python3.6/site-packages/IPython/core/ultratb.py\", line 1336, in structured_traceback\n",
      "    self, etype, value, tb, tb_offset, number_of_lines_of_context\n",
      "  File \"/Users/kimyoonseo/opt/anaconda3/envs/myvenv/lib/python3.6/site-packages/IPython/core/ultratb.py\", line 1193, in structured_traceback\n",
      "    tb_offset)\n",
      "  File \"/Users/kimyoonseo/opt/anaconda3/envs/myvenv/lib/python3.6/site-packages/IPython/core/ultratb.py\", line 1150, in format_exception_as_a_whole\n",
      "    last_unique, recursion_repeat = find_recursion(orig_etype, evalue, records)\n",
      "  File \"/Users/kimyoonseo/opt/anaconda3/envs/myvenv/lib/python3.6/site-packages/IPython/core/ultratb.py\", line 451, in find_recursion\n",
      "    return len(records), 0\n",
      "TypeError: object of type 'NoneType' has no len()\n",
      "\n",
      "During handling of the above exception, another exception occurred:\n",
      "\n",
      "Traceback (most recent call last):\n",
      "  File \"/Users/kimyoonseo/opt/anaconda3/envs/myvenv/lib/python3.6/site-packages/IPython/core/interactiveshell.py\", line 2044, in showtraceback\n",
      "    stb = value._render_traceback_()\n",
      "AttributeError: 'TypeError' object has no attribute '_render_traceback_'\n",
      "\n",
      "During handling of the above exception, another exception occurred:\n",
      "\n",
      "Traceback (most recent call last):\n",
      "  File \"/Users/kimyoonseo/opt/anaconda3/envs/myvenv/lib/python3.6/site-packages/IPython/core/interactiveshell.py\", line 2895, in _run_cell\n",
      "    return runner(coro)\n",
      "  File \"/Users/kimyoonseo/opt/anaconda3/envs/myvenv/lib/python3.6/site-packages/IPython/core/async_helpers.py\", line 68, in _pseudo_sync_runner\n",
      "    coro.send(None)\n",
      "  File \"/Users/kimyoonseo/opt/anaconda3/envs/myvenv/lib/python3.6/site-packages/IPython/core/interactiveshell.py\", line 3072, in run_cell_async\n",
      "    interactivity=interactivity, compiler=compiler, result=result)\n",
      "  File \"/Users/kimyoonseo/opt/anaconda3/envs/myvenv/lib/python3.6/site-packages/IPython/core/interactiveshell.py\", line 3282, in run_ast_nodes\n",
      "    self.showtraceback()\n",
      "  File \"/Users/kimyoonseo/opt/anaconda3/envs/myvenv/lib/python3.6/site-packages/IPython/core/interactiveshell.py\", line 2047, in showtraceback\n",
      "    value, tb, tb_offset=tb_offset)\n",
      "  File \"/Users/kimyoonseo/opt/anaconda3/envs/myvenv/lib/python3.6/site-packages/IPython/core/ultratb.py\", line 1436, in structured_traceback\n",
      "    self, etype, value, tb, tb_offset, number_of_lines_of_context)\n",
      "  File \"/Users/kimyoonseo/opt/anaconda3/envs/myvenv/lib/python3.6/site-packages/IPython/core/ultratb.py\", line 1336, in structured_traceback\n",
      "    self, etype, value, tb, tb_offset, number_of_lines_of_context\n",
      "  File \"/Users/kimyoonseo/opt/anaconda3/envs/myvenv/lib/python3.6/site-packages/IPython/core/ultratb.py\", line 1211, in structured_traceback\n",
      "    chained_exceptions_tb_offset)\n",
      "  File \"/Users/kimyoonseo/opt/anaconda3/envs/myvenv/lib/python3.6/site-packages/IPython/core/ultratb.py\", line 1150, in format_exception_as_a_whole\n",
      "    last_unique, recursion_repeat = find_recursion(orig_etype, evalue, records)\n",
      "  File \"/Users/kimyoonseo/opt/anaconda3/envs/myvenv/lib/python3.6/site-packages/IPython/core/ultratb.py\", line 451, in find_recursion\n",
      "    return len(records), 0\n",
      "TypeError: object of type 'NoneType' has no len()\n",
      "\n",
      "During handling of the above exception, another exception occurred:\n",
      "\n",
      "Traceback (most recent call last):\n",
      "  File \"/Users/kimyoonseo/opt/anaconda3/envs/myvenv/lib/python3.6/site-packages/IPython/core/interactiveshell.py\", line 2044, in showtraceback\n",
      "    stb = value._render_traceback_()\n",
      "AttributeError: 'TypeError' object has no attribute '_render_traceback_'\n",
      "\n",
      "During handling of the above exception, another exception occurred:\n",
      "\n",
      "Traceback (most recent call last):\n",
      "  File \"/Users/kimyoonseo/opt/anaconda3/envs/myvenv/lib/python3.6/site-packages/IPython/core/ultratb.py\", line 1169, in get_records\n",
      "    return _fixed_getinnerframes(etb, number_of_lines_of_context, tb_offset)\n",
      "  File \"/Users/kimyoonseo/opt/anaconda3/envs/myvenv/lib/python3.6/site-packages/IPython/core/ultratb.py\", line 316, in wrapped\n",
      "    return f(*args, **kwargs)\n",
      "  File \"/Users/kimyoonseo/opt/anaconda3/envs/myvenv/lib/python3.6/site-packages/IPython/core/ultratb.py\", line 350, in _fixed_getinnerframes\n",
      "    records = fix_frame_records_filenames(inspect.getinnerframes(etb, context))\n",
      "  File \"/Users/kimyoonseo/opt/anaconda3/envs/myvenv/lib/python3.6/inspect.py\", line 1490, in getinnerframes\n",
      "    frameinfo = (tb.tb_frame,) + getframeinfo(tb, context)\n",
      "  File \"/Users/kimyoonseo/opt/anaconda3/envs/myvenv/lib/python3.6/inspect.py\", line 1448, in getframeinfo\n",
      "    filename = getsourcefile(frame) or getfile(frame)\n",
      "  File \"/Users/kimyoonseo/opt/anaconda3/envs/myvenv/lib/python3.6/inspect.py\", line 696, in getsourcefile\n",
      "    if getattr(getmodule(object, filename), '__loader__', None) is not None:\n",
      "  File \"/Users/kimyoonseo/opt/anaconda3/envs/myvenv/lib/python3.6/inspect.py\", line 733, in getmodule\n",
      "    if ismodule(module) and hasattr(module, '__file__'):\n",
      "  File \"/Users/kimyoonseo/opt/anaconda3/envs/myvenv/lib/python3.6/site-packages/tensorflow/__init__.py\", line 50, in __getattr__\n",
      "    module = self._load()\n",
      "  File \"/Users/kimyoonseo/opt/anaconda3/envs/myvenv/lib/python3.6/site-packages/tensorflow/__init__.py\", line 44, in _load\n",
      "    module = _importlib.import_module(self.__name__)\n",
      "  File \"/Users/kimyoonseo/opt/anaconda3/envs/myvenv/lib/python3.6/importlib/__init__.py\", line 126, in import_module\n",
      "    return _bootstrap._gcd_import(name[level:], package, level)\n",
      "  File \"<frozen importlib._bootstrap>\", line 994, in _gcd_import\n",
      "  File \"<frozen importlib._bootstrap>\", line 971, in _find_and_load\n",
      "  File \"<frozen importlib._bootstrap>\", line 941, in _find_and_load_unlocked\n",
      "  File \"<frozen importlib._bootstrap>\", line 219, in _call_with_frames_removed\n",
      "  File \"<frozen importlib._bootstrap>\", line 994, in _gcd_import\n",
      "  File \"<frozen importlib._bootstrap>\", line 971, in _find_and_load\n",
      "  File \"<frozen importlib._bootstrap>\", line 955, in _find_and_load_unlocked\n",
      "  File \"<frozen importlib._bootstrap>\", line 665, in _load_unlocked\n",
      "  File \"<frozen importlib._bootstrap_external>\", line 678, in exec_module\n",
      "  File \"<frozen importlib._bootstrap>\", line 219, in _call_with_frames_removed\n",
      "  File \"/Users/kimyoonseo/opt/anaconda3/envs/myvenv/lib/python3.6/site-packages/tensorflow_core/__init__.py\", line 42, in <module>\n",
      "    from . _api.v2 import audio\n",
      "  File \"/Users/kimyoonseo/opt/anaconda3/envs/myvenv/lib/python3.6/site-packages/tensorflow_core/_api/v2/audio/__init__.py\", line 10, in <module>\n",
      "    from tensorflow.python.ops.gen_audio_ops import decode_wav\n",
      "  File \"/Users/kimyoonseo/opt/anaconda3/envs/myvenv/lib/python3.6/site-packages/tensorflow_core/python/ops/gen_audio_ops.py\", line 11, in <module>\n",
      "    from tensorflow.python.eager import context as _context\n",
      "  File \"/Users/kimyoonseo/opt/anaconda3/envs/myvenv/lib/python3.6/site-packages/tensorflow_core/python/eager/context.py\", line 29, in <module>\n",
      "    from tensorflow.core.protobuf import config_pb2\n",
      "  File \"/Users/kimyoonseo/opt/anaconda3/envs/myvenv/lib/python3.6/site-packages/tensorflow_core/core/protobuf/config_pb2.py\", line 7, in <module>\n",
      "    from google.protobuf import descriptor as _descriptor\n",
      "ModuleNotFoundError: No module named 'google.protobuf'\n"
     ]
    }
   ],
   "source": [
    "# 그래프 실행 -> 리턴값 있으면 리턴\n",
    "sess = tf.Session()\n",
    "print(\"sess.run([node1, node2])\", sess.run([node1, node2]))\n",
    "print(\"sess.run(node3)\", sess.run(node3))"
   ],
   "metadata": {
    "collapsed": false,
    "pycharm": {
     "name": "#%%\n",
     "is_executing": true
    }
   }
  },
  {
   "cell_type": "code",
   "execution_count": null,
   "outputs": [
    {
     "name": "stderr",
     "output_type": "stream",
     "text": [
      "ERROR:root:Internal Python error in the inspect module.\n",
      "Below is the traceback from this internal error.\n",
      "\n",
      "ERROR:root:Internal Python error in the inspect module.\n",
      "Below is the traceback from this internal error.\n",
      "\n",
      "ERROR:root:Internal Python error in the inspect module.\n",
      "Below is the traceback from this internal error.\n",
      "\n"
     ]
    },
    {
     "name": "stdout",
     "output_type": "stream",
     "text": [
      "ERROR! Session/line number was not unique in database. History logging moved to new session 64\n",
      "Traceback (most recent call last):\n",
      "  File \"/Users/kimyoonseo/opt/anaconda3/envs/myvenv/lib/python3.6/site-packages/IPython/core/interactiveshell.py\", line 3343, in run_code\n",
      "    exec(code_obj, self.user_global_ns, self.user_ns)\n",
      "  File \"<ipython-input-12-2b2bc2fa3be4>\", line 2, in <module>\n",
      "    a = tf.placeholder(tf.float32)\n",
      "  File \"/Users/kimyoonseo/opt/anaconda3/envs/myvenv/lib/python3.6/site-packages/tensorflow_core/python/util/module_wrapper.py\", line 193, in __getattr__\n",
      "    set([\n",
      "AttributeError: module 'tensorflow' has no attribute 'placeholder'\n",
      "\n",
      "During handling of the above exception, another exception occurred:\n",
      "\n",
      "Traceback (most recent call last):\n",
      "  File \"/Users/kimyoonseo/opt/anaconda3/envs/myvenv/lib/python3.6/site-packages/IPython/core/interactiveshell.py\", line 2044, in showtraceback\n",
      "    stb = value._render_traceback_()\n",
      "AttributeError: 'AttributeError' object has no attribute '_render_traceback_'\n",
      "\n",
      "During handling of the above exception, another exception occurred:\n",
      "\n",
      "Traceback (most recent call last):\n",
      "  File \"/Users/kimyoonseo/opt/anaconda3/envs/myvenv/lib/python3.6/site-packages/IPython/core/ultratb.py\", line 1169, in get_records\n",
      "    return _fixed_getinnerframes(etb, number_of_lines_of_context, tb_offset)\n",
      "  File \"/Users/kimyoonseo/opt/anaconda3/envs/myvenv/lib/python3.6/site-packages/IPython/core/ultratb.py\", line 316, in wrapped\n",
      "    return f(*args, **kwargs)\n",
      "  File \"/Users/kimyoonseo/opt/anaconda3/envs/myvenv/lib/python3.6/site-packages/IPython/core/ultratb.py\", line 350, in _fixed_getinnerframes\n",
      "    records = fix_frame_records_filenames(inspect.getinnerframes(etb, context))\n",
      "  File \"/Users/kimyoonseo/opt/anaconda3/envs/myvenv/lib/python3.6/inspect.py\", line 1490, in getinnerframes\n",
      "    frameinfo = (tb.tb_frame,) + getframeinfo(tb, context)\n",
      "  File \"/Users/kimyoonseo/opt/anaconda3/envs/myvenv/lib/python3.6/inspect.py\", line 1448, in getframeinfo\n",
      "    filename = getsourcefile(frame) or getfile(frame)\n",
      "  File \"/Users/kimyoonseo/opt/anaconda3/envs/myvenv/lib/python3.6/inspect.py\", line 696, in getsourcefile\n",
      "    if getattr(getmodule(object, filename), '__loader__', None) is not None:\n",
      "  File \"/Users/kimyoonseo/opt/anaconda3/envs/myvenv/lib/python3.6/inspect.py\", line 733, in getmodule\n",
      "    if ismodule(module) and hasattr(module, '__file__'):\n",
      "  File \"/Users/kimyoonseo/opt/anaconda3/envs/myvenv/lib/python3.6/site-packages/tensorflow/__init__.py\", line 50, in __getattr__\n",
      "    module = self._load()\n",
      "  File \"/Users/kimyoonseo/opt/anaconda3/envs/myvenv/lib/python3.6/site-packages/tensorflow/__init__.py\", line 44, in _load\n",
      "    module = _importlib.import_module(self.__name__)\n",
      "  File \"/Users/kimyoonseo/opt/anaconda3/envs/myvenv/lib/python3.6/importlib/__init__.py\", line 126, in import_module\n",
      "    return _bootstrap._gcd_import(name[level:], package, level)\n",
      "  File \"<frozen importlib._bootstrap>\", line 994, in _gcd_import\n",
      "  File \"<frozen importlib._bootstrap>\", line 971, in _find_and_load\n",
      "  File \"<frozen importlib._bootstrap>\", line 941, in _find_and_load_unlocked\n",
      "  File \"<frozen importlib._bootstrap>\", line 219, in _call_with_frames_removed\n",
      "  File \"<frozen importlib._bootstrap>\", line 994, in _gcd_import\n",
      "  File \"<frozen importlib._bootstrap>\", line 971, in _find_and_load\n",
      "  File \"<frozen importlib._bootstrap>\", line 955, in _find_and_load_unlocked\n",
      "  File \"<frozen importlib._bootstrap>\", line 665, in _load_unlocked\n",
      "  File \"<frozen importlib._bootstrap_external>\", line 678, in exec_module\n",
      "  File \"<frozen importlib._bootstrap>\", line 219, in _call_with_frames_removed\n",
      "  File \"/Users/kimyoonseo/opt/anaconda3/envs/myvenv/lib/python3.6/site-packages/tensorflow_core/__init__.py\", line 42, in <module>\n",
      "    from . _api.v2 import audio\n",
      "  File \"/Users/kimyoonseo/opt/anaconda3/envs/myvenv/lib/python3.6/site-packages/tensorflow_core/_api/v2/audio/__init__.py\", line 10, in <module>\n",
      "    from tensorflow.python.ops.gen_audio_ops import decode_wav\n",
      "  File \"/Users/kimyoonseo/opt/anaconda3/envs/myvenv/lib/python3.6/site-packages/tensorflow_core/python/ops/gen_audio_ops.py\", line 11, in <module>\n",
      "    from tensorflow.python.eager import context as _context\n",
      "  File \"/Users/kimyoonseo/opt/anaconda3/envs/myvenv/lib/python3.6/site-packages/tensorflow_core/python/eager/context.py\", line 29, in <module>\n",
      "    from tensorflow.core.protobuf import config_pb2\n",
      "  File \"/Users/kimyoonseo/opt/anaconda3/envs/myvenv/lib/python3.6/site-packages/tensorflow_core/core/protobuf/config_pb2.py\", line 7, in <module>\n",
      "    from google.protobuf import descriptor as _descriptor\n",
      "ModuleNotFoundError: No module named 'google.protobuf'\n",
      "Traceback (most recent call last):\n",
      "  File \"/Users/kimyoonseo/opt/anaconda3/envs/myvenv/lib/python3.6/site-packages/IPython/core/interactiveshell.py\", line 3343, in run_code\n",
      "    exec(code_obj, self.user_global_ns, self.user_ns)\n",
      "  File \"<ipython-input-12-2b2bc2fa3be4>\", line 2, in <module>\n",
      "    a = tf.placeholder(tf.float32)\n",
      "  File \"/Users/kimyoonseo/opt/anaconda3/envs/myvenv/lib/python3.6/site-packages/tensorflow_core/python/util/module_wrapper.py\", line 193, in __getattr__\n",
      "    set([\n",
      "AttributeError: module 'tensorflow' has no attribute 'placeholder'\n",
      "\n",
      "During handling of the above exception, another exception occurred:\n",
      "\n",
      "Traceback (most recent call last):\n",
      "  File \"/Users/kimyoonseo/opt/anaconda3/envs/myvenv/lib/python3.6/site-packages/IPython/core/interactiveshell.py\", line 2044, in showtraceback\n",
      "    stb = value._render_traceback_()\n",
      "AttributeError: 'AttributeError' object has no attribute '_render_traceback_'\n",
      "\n",
      "During handling of the above exception, another exception occurred:\n",
      "\n",
      "Traceback (most recent call last):\n",
      "  File \"/Users/kimyoonseo/opt/anaconda3/envs/myvenv/lib/python3.6/site-packages/IPython/core/interactiveshell.py\", line 3263, in run_ast_nodes\n",
      "    if (await self.run_code(code, result,  async_=asy)):\n",
      "  File \"/Users/kimyoonseo/opt/anaconda3/envs/myvenv/lib/python3.6/site-packages/IPython/core/interactiveshell.py\", line 3360, in run_code\n",
      "    self.showtraceback(running_compiled_code=True)\n",
      "  File \"/Users/kimyoonseo/opt/anaconda3/envs/myvenv/lib/python3.6/site-packages/IPython/core/interactiveshell.py\", line 2047, in showtraceback\n",
      "    value, tb, tb_offset=tb_offset)\n",
      "  File \"/Users/kimyoonseo/opt/anaconda3/envs/myvenv/lib/python3.6/site-packages/IPython/core/ultratb.py\", line 1436, in structured_traceback\n",
      "    self, etype, value, tb, tb_offset, number_of_lines_of_context)\n",
      "  File \"/Users/kimyoonseo/opt/anaconda3/envs/myvenv/lib/python3.6/site-packages/IPython/core/ultratb.py\", line 1336, in structured_traceback\n",
      "    self, etype, value, tb, tb_offset, number_of_lines_of_context\n",
      "  File \"/Users/kimyoonseo/opt/anaconda3/envs/myvenv/lib/python3.6/site-packages/IPython/core/ultratb.py\", line 1193, in structured_traceback\n",
      "    tb_offset)\n",
      "  File \"/Users/kimyoonseo/opt/anaconda3/envs/myvenv/lib/python3.6/site-packages/IPython/core/ultratb.py\", line 1150, in format_exception_as_a_whole\n",
      "    last_unique, recursion_repeat = find_recursion(orig_etype, evalue, records)\n",
      "  File \"/Users/kimyoonseo/opt/anaconda3/envs/myvenv/lib/python3.6/site-packages/IPython/core/ultratb.py\", line 451, in find_recursion\n",
      "    return len(records), 0\n",
      "TypeError: object of type 'NoneType' has no len()\n",
      "\n",
      "During handling of the above exception, another exception occurred:\n",
      "\n",
      "Traceback (most recent call last):\n",
      "  File \"/Users/kimyoonseo/opt/anaconda3/envs/myvenv/lib/python3.6/site-packages/IPython/core/interactiveshell.py\", line 2044, in showtraceback\n",
      "    stb = value._render_traceback_()\n",
      "AttributeError: 'TypeError' object has no attribute '_render_traceback_'\n",
      "\n",
      "During handling of the above exception, another exception occurred:\n",
      "\n",
      "Traceback (most recent call last):\n",
      "  File \"/Users/kimyoonseo/opt/anaconda3/envs/myvenv/lib/python3.6/site-packages/IPython/core/ultratb.py\", line 1169, in get_records\n",
      "    return _fixed_getinnerframes(etb, number_of_lines_of_context, tb_offset)\n",
      "  File \"/Users/kimyoonseo/opt/anaconda3/envs/myvenv/lib/python3.6/site-packages/IPython/core/ultratb.py\", line 316, in wrapped\n",
      "    return f(*args, **kwargs)\n",
      "  File \"/Users/kimyoonseo/opt/anaconda3/envs/myvenv/lib/python3.6/site-packages/IPython/core/ultratb.py\", line 350, in _fixed_getinnerframes\n",
      "    records = fix_frame_records_filenames(inspect.getinnerframes(etb, context))\n",
      "  File \"/Users/kimyoonseo/opt/anaconda3/envs/myvenv/lib/python3.6/inspect.py\", line 1490, in getinnerframes\n",
      "    frameinfo = (tb.tb_frame,) + getframeinfo(tb, context)\n",
      "  File \"/Users/kimyoonseo/opt/anaconda3/envs/myvenv/lib/python3.6/inspect.py\", line 1448, in getframeinfo\n",
      "    filename = getsourcefile(frame) or getfile(frame)\n",
      "  File \"/Users/kimyoonseo/opt/anaconda3/envs/myvenv/lib/python3.6/inspect.py\", line 696, in getsourcefile\n",
      "    if getattr(getmodule(object, filename), '__loader__', None) is not None:\n",
      "  File \"/Users/kimyoonseo/opt/anaconda3/envs/myvenv/lib/python3.6/inspect.py\", line 733, in getmodule\n",
      "    if ismodule(module) and hasattr(module, '__file__'):\n",
      "  File \"/Users/kimyoonseo/opt/anaconda3/envs/myvenv/lib/python3.6/site-packages/tensorflow/__init__.py\", line 50, in __getattr__\n",
      "    module = self._load()\n",
      "  File \"/Users/kimyoonseo/opt/anaconda3/envs/myvenv/lib/python3.6/site-packages/tensorflow/__init__.py\", line 44, in _load\n",
      "    module = _importlib.import_module(self.__name__)\n",
      "  File \"/Users/kimyoonseo/opt/anaconda3/envs/myvenv/lib/python3.6/importlib/__init__.py\", line 126, in import_module\n",
      "    return _bootstrap._gcd_import(name[level:], package, level)\n",
      "  File \"<frozen importlib._bootstrap>\", line 994, in _gcd_import\n",
      "  File \"<frozen importlib._bootstrap>\", line 971, in _find_and_load\n",
      "  File \"<frozen importlib._bootstrap>\", line 941, in _find_and_load_unlocked\n",
      "  File \"<frozen importlib._bootstrap>\", line 219, in _call_with_frames_removed\n",
      "  File \"<frozen importlib._bootstrap>\", line 994, in _gcd_import\n",
      "  File \"<frozen importlib._bootstrap>\", line 971, in _find_and_load\n",
      "  File \"<frozen importlib._bootstrap>\", line 955, in _find_and_load_unlocked\n",
      "  File \"<frozen importlib._bootstrap>\", line 665, in _load_unlocked\n",
      "  File \"<frozen importlib._bootstrap_external>\", line 678, in exec_module\n",
      "  File \"<frozen importlib._bootstrap>\", line 219, in _call_with_frames_removed\n",
      "  File \"/Users/kimyoonseo/opt/anaconda3/envs/myvenv/lib/python3.6/site-packages/tensorflow_core/__init__.py\", line 42, in <module>\n",
      "    from . _api.v2 import audio\n",
      "  File \"/Users/kimyoonseo/opt/anaconda3/envs/myvenv/lib/python3.6/site-packages/tensorflow_core/_api/v2/audio/__init__.py\", line 10, in <module>\n",
      "    from tensorflow.python.ops.gen_audio_ops import decode_wav\n",
      "  File \"/Users/kimyoonseo/opt/anaconda3/envs/myvenv/lib/python3.6/site-packages/tensorflow_core/python/ops/gen_audio_ops.py\", line 11, in <module>\n",
      "    from tensorflow.python.eager import context as _context\n",
      "  File \"/Users/kimyoonseo/opt/anaconda3/envs/myvenv/lib/python3.6/site-packages/tensorflow_core/python/eager/context.py\", line 29, in <module>\n",
      "    from tensorflow.core.protobuf import config_pb2\n",
      "  File \"/Users/kimyoonseo/opt/anaconda3/envs/myvenv/lib/python3.6/site-packages/tensorflow_core/core/protobuf/config_pb2.py\", line 7, in <module>\n",
      "    from google.protobuf import descriptor as _descriptor\n",
      "ModuleNotFoundError: No module named 'google.protobuf'\n",
      "Traceback (most recent call last):\n",
      "  File \"/Users/kimyoonseo/opt/anaconda3/envs/myvenv/lib/python3.6/site-packages/IPython/core/interactiveshell.py\", line 3343, in run_code\n",
      "    exec(code_obj, self.user_global_ns, self.user_ns)\n",
      "  File \"<ipython-input-12-2b2bc2fa3be4>\", line 2, in <module>\n",
      "    a = tf.placeholder(tf.float32)\n",
      "  File \"/Users/kimyoonseo/opt/anaconda3/envs/myvenv/lib/python3.6/site-packages/tensorflow_core/python/util/module_wrapper.py\", line 193, in __getattr__\n",
      "    set([\n",
      "AttributeError: module 'tensorflow' has no attribute 'placeholder'\n",
      "\n",
      "During handling of the above exception, another exception occurred:\n",
      "\n",
      "Traceback (most recent call last):\n",
      "  File \"/Users/kimyoonseo/opt/anaconda3/envs/myvenv/lib/python3.6/site-packages/IPython/core/interactiveshell.py\", line 2044, in showtraceback\n",
      "    stb = value._render_traceback_()\n",
      "AttributeError: 'AttributeError' object has no attribute '_render_traceback_'\n",
      "\n",
      "During handling of the above exception, another exception occurred:\n",
      "\n",
      "Traceback (most recent call last):\n",
      "  File \"/Users/kimyoonseo/opt/anaconda3/envs/myvenv/lib/python3.6/site-packages/IPython/core/interactiveshell.py\", line 3263, in run_ast_nodes\n",
      "    if (await self.run_code(code, result,  async_=asy)):\n",
      "  File \"/Users/kimyoonseo/opt/anaconda3/envs/myvenv/lib/python3.6/site-packages/IPython/core/interactiveshell.py\", line 3360, in run_code\n",
      "    self.showtraceback(running_compiled_code=True)\n",
      "  File \"/Users/kimyoonseo/opt/anaconda3/envs/myvenv/lib/python3.6/site-packages/IPython/core/interactiveshell.py\", line 2047, in showtraceback\n",
      "    value, tb, tb_offset=tb_offset)\n",
      "  File \"/Users/kimyoonseo/opt/anaconda3/envs/myvenv/lib/python3.6/site-packages/IPython/core/ultratb.py\", line 1436, in structured_traceback\n",
      "    self, etype, value, tb, tb_offset, number_of_lines_of_context)\n",
      "  File \"/Users/kimyoonseo/opt/anaconda3/envs/myvenv/lib/python3.6/site-packages/IPython/core/ultratb.py\", line 1336, in structured_traceback\n",
      "    self, etype, value, tb, tb_offset, number_of_lines_of_context\n",
      "  File \"/Users/kimyoonseo/opt/anaconda3/envs/myvenv/lib/python3.6/site-packages/IPython/core/ultratb.py\", line 1193, in structured_traceback\n",
      "    tb_offset)\n",
      "  File \"/Users/kimyoonseo/opt/anaconda3/envs/myvenv/lib/python3.6/site-packages/IPython/core/ultratb.py\", line 1150, in format_exception_as_a_whole\n",
      "    last_unique, recursion_repeat = find_recursion(orig_etype, evalue, records)\n",
      "  File \"/Users/kimyoonseo/opt/anaconda3/envs/myvenv/lib/python3.6/site-packages/IPython/core/ultratb.py\", line 451, in find_recursion\n",
      "    return len(records), 0\n",
      "TypeError: object of type 'NoneType' has no len()\n",
      "\n",
      "During handling of the above exception, another exception occurred:\n",
      "\n",
      "Traceback (most recent call last):\n",
      "  File \"/Users/kimyoonseo/opt/anaconda3/envs/myvenv/lib/python3.6/site-packages/IPython/core/interactiveshell.py\", line 2044, in showtraceback\n",
      "    stb = value._render_traceback_()\n",
      "AttributeError: 'TypeError' object has no attribute '_render_traceback_'\n",
      "\n",
      "During handling of the above exception, another exception occurred:\n",
      "\n",
      "Traceback (most recent call last):\n",
      "  File \"/Users/kimyoonseo/opt/anaconda3/envs/myvenv/lib/python3.6/site-packages/IPython/core/interactiveshell.py\", line 2895, in _run_cell\n",
      "    return runner(coro)\n",
      "  File \"/Users/kimyoonseo/opt/anaconda3/envs/myvenv/lib/python3.6/site-packages/IPython/core/async_helpers.py\", line 68, in _pseudo_sync_runner\n",
      "    coro.send(None)\n",
      "  File \"/Users/kimyoonseo/opt/anaconda3/envs/myvenv/lib/python3.6/site-packages/IPython/core/interactiveshell.py\", line 3072, in run_cell_async\n",
      "    interactivity=interactivity, compiler=compiler, result=result)\n",
      "  File \"/Users/kimyoonseo/opt/anaconda3/envs/myvenv/lib/python3.6/site-packages/IPython/core/interactiveshell.py\", line 3282, in run_ast_nodes\n",
      "    self.showtraceback()\n",
      "  File \"/Users/kimyoonseo/opt/anaconda3/envs/myvenv/lib/python3.6/site-packages/IPython/core/interactiveshell.py\", line 2047, in showtraceback\n",
      "    value, tb, tb_offset=tb_offset)\n",
      "  File \"/Users/kimyoonseo/opt/anaconda3/envs/myvenv/lib/python3.6/site-packages/IPython/core/ultratb.py\", line 1436, in structured_traceback\n",
      "    self, etype, value, tb, tb_offset, number_of_lines_of_context)\n",
      "  File \"/Users/kimyoonseo/opt/anaconda3/envs/myvenv/lib/python3.6/site-packages/IPython/core/ultratb.py\", line 1336, in structured_traceback\n",
      "    self, etype, value, tb, tb_offset, number_of_lines_of_context\n",
      "  File \"/Users/kimyoonseo/opt/anaconda3/envs/myvenv/lib/python3.6/site-packages/IPython/core/ultratb.py\", line 1211, in structured_traceback\n",
      "    chained_exceptions_tb_offset)\n",
      "  File \"/Users/kimyoonseo/opt/anaconda3/envs/myvenv/lib/python3.6/site-packages/IPython/core/ultratb.py\", line 1150, in format_exception_as_a_whole\n",
      "    last_unique, recursion_repeat = find_recursion(orig_etype, evalue, records)\n",
      "  File \"/Users/kimyoonseo/opt/anaconda3/envs/myvenv/lib/python3.6/site-packages/IPython/core/ultratb.py\", line 451, in find_recursion\n",
      "    return len(records), 0\n",
      "TypeError: object of type 'NoneType' has no len()\n",
      "\n",
      "During handling of the above exception, another exception occurred:\n",
      "\n",
      "Traceback (most recent call last):\n",
      "  File \"/Users/kimyoonseo/opt/anaconda3/envs/myvenv/lib/python3.6/site-packages/IPython/core/interactiveshell.py\", line 2044, in showtraceback\n",
      "    stb = value._render_traceback_()\n",
      "AttributeError: 'TypeError' object has no attribute '_render_traceback_'\n",
      "\n",
      "During handling of the above exception, another exception occurred:\n",
      "\n",
      "Traceback (most recent call last):\n",
      "  File \"/Users/kimyoonseo/opt/anaconda3/envs/myvenv/lib/python3.6/site-packages/IPython/core/ultratb.py\", line 1169, in get_records\n",
      "    return _fixed_getinnerframes(etb, number_of_lines_of_context, tb_offset)\n",
      "  File \"/Users/kimyoonseo/opt/anaconda3/envs/myvenv/lib/python3.6/site-packages/IPython/core/ultratb.py\", line 316, in wrapped\n",
      "    return f(*args, **kwargs)\n",
      "  File \"/Users/kimyoonseo/opt/anaconda3/envs/myvenv/lib/python3.6/site-packages/IPython/core/ultratb.py\", line 350, in _fixed_getinnerframes\n",
      "    records = fix_frame_records_filenames(inspect.getinnerframes(etb, context))\n",
      "  File \"/Users/kimyoonseo/opt/anaconda3/envs/myvenv/lib/python3.6/inspect.py\", line 1490, in getinnerframes\n",
      "    frameinfo = (tb.tb_frame,) + getframeinfo(tb, context)\n",
      "  File \"/Users/kimyoonseo/opt/anaconda3/envs/myvenv/lib/python3.6/inspect.py\", line 1448, in getframeinfo\n",
      "    filename = getsourcefile(frame) or getfile(frame)\n",
      "  File \"/Users/kimyoonseo/opt/anaconda3/envs/myvenv/lib/python3.6/inspect.py\", line 696, in getsourcefile\n",
      "    if getattr(getmodule(object, filename), '__loader__', None) is not None:\n",
      "  File \"/Users/kimyoonseo/opt/anaconda3/envs/myvenv/lib/python3.6/inspect.py\", line 733, in getmodule\n",
      "    if ismodule(module) and hasattr(module, '__file__'):\n",
      "  File \"/Users/kimyoonseo/opt/anaconda3/envs/myvenv/lib/python3.6/site-packages/tensorflow/__init__.py\", line 50, in __getattr__\n",
      "    module = self._load()\n",
      "  File \"/Users/kimyoonseo/opt/anaconda3/envs/myvenv/lib/python3.6/site-packages/tensorflow/__init__.py\", line 44, in _load\n",
      "    module = _importlib.import_module(self.__name__)\n",
      "  File \"/Users/kimyoonseo/opt/anaconda3/envs/myvenv/lib/python3.6/importlib/__init__.py\", line 126, in import_module\n",
      "    return _bootstrap._gcd_import(name[level:], package, level)\n",
      "  File \"<frozen importlib._bootstrap>\", line 994, in _gcd_import\n",
      "  File \"<frozen importlib._bootstrap>\", line 971, in _find_and_load\n",
      "  File \"<frozen importlib._bootstrap>\", line 941, in _find_and_load_unlocked\n",
      "  File \"<frozen importlib._bootstrap>\", line 219, in _call_with_frames_removed\n",
      "  File \"<frozen importlib._bootstrap>\", line 994, in _gcd_import\n",
      "  File \"<frozen importlib._bootstrap>\", line 971, in _find_and_load\n",
      "  File \"<frozen importlib._bootstrap>\", line 955, in _find_and_load_unlocked\n",
      "  File \"<frozen importlib._bootstrap>\", line 665, in _load_unlocked\n",
      "  File \"<frozen importlib._bootstrap_external>\", line 678, in exec_module\n",
      "  File \"<frozen importlib._bootstrap>\", line 219, in _call_with_frames_removed\n",
      "  File \"/Users/kimyoonseo/opt/anaconda3/envs/myvenv/lib/python3.6/site-packages/tensorflow_core/__init__.py\", line 42, in <module>\n",
      "    from . _api.v2 import audio\n",
      "  File \"/Users/kimyoonseo/opt/anaconda3/envs/myvenv/lib/python3.6/site-packages/tensorflow_core/_api/v2/audio/__init__.py\", line 10, in <module>\n",
      "    from tensorflow.python.ops.gen_audio_ops import decode_wav\n",
      "  File \"/Users/kimyoonseo/opt/anaconda3/envs/myvenv/lib/python3.6/site-packages/tensorflow_core/python/ops/gen_audio_ops.py\", line 11, in <module>\n",
      "    from tensorflow.python.eager import context as _context\n",
      "  File \"/Users/kimyoonseo/opt/anaconda3/envs/myvenv/lib/python3.6/site-packages/tensorflow_core/python/eager/context.py\", line 29, in <module>\n",
      "    from tensorflow.core.protobuf import config_pb2\n",
      "  File \"/Users/kimyoonseo/opt/anaconda3/envs/myvenv/lib/python3.6/site-packages/tensorflow_core/core/protobuf/config_pb2.py\", line 7, in <module>\n",
      "    from google.protobuf import descriptor as _descriptor\n",
      "ModuleNotFoundError: No module named 'google.protobuf'\n"
     ]
    }
   ],
   "source": [
    "# Placeholder\n",
    "a = tf.placeholder(tf.float32)\n",
    "b = tf.placeholder(tf.float32)\n",
    "adder_node = a+b\n",
    "\n",
    "print(sess.run(adder_node, feed_dict={a: 3, b: 4.5}))\n",
    "print(sess.run(adder_node, feed_dict={a: [1, 3], b: [2, 4]}))"
   ],
   "metadata": {
    "collapsed": false,
    "pycharm": {
     "name": "#%%\n",
     "is_executing": true
    }
   }
  },
  {
   "cell_type": "code",
   "execution_count": 11,
   "outputs": [],
   "source": [],
   "metadata": {
    "collapsed": false,
    "pycharm": {
     "name": "#%%\n"
    }
   }
  },
  {
   "cell_type": "code",
   "execution_count": null,
   "outputs": [],
   "source": [],
   "metadata": {
    "collapsed": false,
    "pycharm": {
     "name": "#%%\n"
    }
   }
  }
 ],
 "metadata": {
  "kernelspec": {
   "display_name": "Python 3",
   "language": "python",
   "name": "python3"
  },
  "language_info": {
   "codemirror_mode": {
    "name": "ipython",
    "version": 2
   },
   "file_extension": ".py",
   "mimetype": "text/x-python",
   "name": "python",
   "nbconvert_exporter": "python",
   "pygments_lexer": "ipython2",
   "version": "2.7.6"
  }
 },
 "nbformat": 4,
 "nbformat_minor": 0
}